Workbook

Sheet Инструкция
A1: РАСЧЁТ ЗАРПЛАТЫ · Alisher Karimov · Constantia Intensivpflege GmbH
B3: Источники: Arbeitsvertrag от 01.08.2026 (§§ 1–19), EzB от 13.07.2026, ArbZG, EStG (§ 3b, § 32a, § 39b), SvEV, BUrlG, EFZG, PflegeArbbV
A5: ЛИСТЫ ФАЙЛА
B6: Настройки | C6: Все параметры: ставка, надбавки, время смен, лимит переработки, налоговый класс. Жёлтое — можно менять.
B7: Dienstplan | C7: График месяца: ND / TD / FREI, статус (Arbeit / Urlaub / Krank), «x» = Eingesprungen. Сейчас заполнен СЕНТЯБРЬ 2026: 15 TD + 3 ND = 18 смен = 216 ч.
B8: Расчёт | C8: Брутто, надбавки, счёт часов, соцвзносы, налоги, нетто.
B9: Lohnsteuer | C9: Подоходный налог по методу официального Programmablaufplan.
B10: Контроль ArbZG | C10: Проверка по закону о рабочем времени.
B11: Права и риски | C11: Что в договоре есть, чего нет, и что из этого следует.
B12: Feiertage | C12: Праздники Нижней Саксонии 2026/2027.
B13: Мои данные | C13: Пустые поля для SV-Nummer, Steuer-ID и т.д. Заполни у себя — файл лежит в ПУБЛИЧНОМ репозитории GitHub.
B14: Год | C14: Сводка по 12 месяцам и счёт переносимых часов.
B15: Сверка с расчёткой | C15: Реальные Lohnabrechnung 07/2026 и 08/2026, разобранные построчно, и проверка каждой суммы. Август зафиксирован числами и не меняется при смене месяца.
A17: ВАЖНО ПРО ФОРМАТ
B18: Время смен — это ЧИСЛА | C18: 20 = 20:00, 8 = 08:00, 6,5 = 06:30. Так сделано специально: Numbers на iPhone/Mac ломает формулы с настоящими значениями времени.
B19: Numbers убирает подсветку | C19: Цветные предупреждения Numbers удаляет. Поэтому все предупреждения продублированы ТЕКСТОМ в последней колонке Dienstplan и на листе «Контроль ArbZG».
B20: Если что-то показывает ошибку | C20: Открой в Excel, Google Sheets или LibreOffice — там работает всё. В Numbers формулы тоже работают, но подсветка и выпадающие списки пропадают.
A22: ЧТО ГОВОРИТ ДОГОВОР (§ 3 Vergütung)
B23: Часовая ставка | C23: 27,00 € брутто (§ 3 Abs. 1)
B24: Оклад в месяц | C24: 4.676,40 € брутто → норма 4.676,40 / 27,00 = 173,20 ч/мес
B25: Рабочее время | C25: 40 ч в неделю, пятидневка, БЕЗ учёта перерывов (§ 2 Abs. 1)
B26: Ночь 20:00–06:00 | C26: +25 % (§ 3 Abs. 2 a)
B27: Воскресенье 00:00–24:00 | C27: +50 % (§ 3 Abs. 2 b)
B28: Праздник с отгулом (mit FZA) | C28: +35 % (§ 3 Abs. 2 c)
B29: Праздник без отгула (ohne FZA) | C29: +135 % (§ 3 Abs. 2 d)
B30: Совпадение надбавок | C30: Платится ТОЛЬКО САМАЯ ВЫСОКАЯ. Ночь в воскресенье = 50 %, не 75 %.
B31: Твои смены | C31: ND 20:00–08:00 = 12 ч, из них 10 ч ночных (20:00–06:00) и 2 ч обычных (06:00–08:00). TD 08:00–20:00 = 12 ч, ночных 0.
B32: Переработка | C32: § 2 Abs. 3: первые 8 ч/мес включены в оклад. Работодатель на практике оплачивает максимум 60 ч/мес, остальное переносит в следующий месяц отгулами — в договоре этого правила НЕТ, см. лист «Права и риски».
B33: Выплата | C33: 15-го числа следующего месяца (§ 3 Abs. 3)
B34: Срок претензий | C34: 3 месяца — § 14 Ausschlussfrist. Пропустил — право пропало.
A36: НАЛОГИ И ВЗНОСЫ
B37: § 3b EStG | C37: Надбавки за ночь/воскресенье/праздник свободны от подоходного налога: ночь до 25 %, воскресенье до 50 %, праздник до 125 % (01.05, 25./26.12 и 24.12 с 14:00 — до 150 %). База — максимум 50 €/ч.
B38: § 1 Abs. 1 SvEV | C38: От соцвзносов надбавки свободны только с базы 25,00 €/ч. Ставка 27,00 € → часть надбавки, посчитанная с 2,00 €/ч, взносами облагается. Файл делит автоматически.
B39: Отпуск и больничный | C39: Надбавки, выплаченные за дни отпуска/болезни, налогом ОБЛАГАЮТСЯ — § 3b требует фактической работы. Ставь статус Urlaub/Krank.
B40: Налоговый класс 3, 1 ребёнок | C40: Считается по Splittingtarif. Ребёнок с 2025 г. → доплата бездетных в Pflegeversicherung (0,6 %) больше НЕ удерживается — проверь это в Lohnabrechnung.
A42: ТОЧНОСТЬ
B43: Часы, надбавки, брутто | C43: Точно — по формулам договора.
B44: Соцвзносы | C44: Точно — ставки и предельные базы 2026.
B45: Подоходный налог | C45: Оценка ±несколько евро. Классы 5 и 6 не поддерживаются.
B46: Нетто | C46: Оценка. Официальный документ — Lohnabrechnung. Этот файл нужен, чтобы её проверить.
...

Sheet Настройки
A1: НАСТРОЙКИ / EINSTELLUNGEN — жёлтые поля можно менять
B3: 1. РАСЧЁТНЫЙ МЕСЯЦ
B4: Год | C4: Jahr | D4: 2026
B5: Месяц (1–12) | C5: Monat | D5: 9
B6: Дней в месяце | C6: Tage im Monat | D6: =DAY(EOMONTH(DATE(Настройки!$D$4,Настройки!$D$5,1),0))
B7: Федеральная земля | C7: Bundesland | D7: Niedersachsen | E7: Праздники — с листа «Feiertage»
B9: 2. ОПЛАТА — § 3 Arbeitsvertrag
B10: Часовая ставка | C10: Stundenlohn (Grundlohn) | D10: 27 | E10: § 3 Abs. 1
B11: Оклад брутто в месяц | C11: Monatsvergütung brutto | D11: 4676.4 | E11: § 3 Abs. 1
B12: Плановые часы в месяц | C12: Sollstunden / Monat | D12: =Настройки!$D$11/Настройки!$D$10 | E12: оклад / ставка = 173,20 ч
B13: Часов в неделю | C13: Wochenarbeitszeit | D13: 40 | E13: § 2 Abs. 1
B14: Переработка включена в оклад (ч) | C14: pauschal abgegoltene Überstunden | D14: 0 | E14: § 2 Abs. 3 договора разрешает не платить первые 8 ч/мес. Но в расчётке 08/2026 оплачены ВСЕ 216 ч — поэтому здесь 0. Поставь 8, если хочешь увидеть минимум по договору
B15: Максимум оплачиваемой переработки (ч) | C15: max. auszahlbare Überstunden | D15: 60 | E15: Практика работодателя: не более 60 ч/мес. В ДОГОВОРЕ такого правила нет — см. лист «Права и риски»
B16: Оплачивать переработку? | C16: Überstunden auszahlen (ja/nein) | D16: ja | E16: «nein» = всё идёт в счёт часов отгулами
B17: Надбавка за переработку | C17: Überstundenzuschlag | D17: 0 | E17: Договором не предусмотрена
B18: Перенос часов из прошлого месяца | C18: Übertrag aus Vormonat | D18: 0 | E18: Остаток счёта часов (Arbeitszeitkonto) на начало месяца
B19: Премия за Eingesprungen (за смену) | C19: Einspringprämie je Dienst | D19: 0 | E19: В договоре НЕТ. Впиши сумму, о которой договорились. Требуй подтверждение по e-mail — см. «Права и риски»
B20: Фактор неполного месяца | C20: Faktor (Ein-/Austritt) | D20: 1 | E20: 1,00 = полный месяц
B22: 3. НАДБАВКИ — § 3 Abs. 2 Arbeitsvertrag
B23: Ночная надбавка | C23: Nachtzuschlag | D23: 0.25 | E23: § 3 Abs. 2 a)
B24: Ночь: с (час) | C24: Nachtarbeit von | D24: 20 | E24: 20 = 20:00. Подтверждено работодателем (Chris, WhatsApp 09/2026): «20:00 – 06:00 morgens Nacht»
B25: Ночь: до (час) | C25: Nachtarbeit bis | D25: 6 | E25: 6 = 06:00
B26: Воскресная надбавка | C26: Sonntagszuschlag | D26: 0.5 | E26: § 3 Abs. 2 b). Подтверждено (Chris): «Sonntags Zuschlag ab 00:00» и «Sonntag > als Nacht, dann zählt Sonntag» — надбавки НЕ складываются
B27: Праздник С отгулом | C27: Feiertag mit FZA | D27: 0.35 | E27: § 3 Abs. 2 c)
B28: Праздник БЕЗ отгула | C28: Feiertag ohne FZA | D28: 1.35 | E28: § 3 Abs. 2 d)
B29: Праздники по умолчанию | C29: Feiertagsmodus | D29: ohne FZA | E29: «mit FZA» / «ohne FZA»; в графике можно задать по дню (колонка FZA: j / n)
B31: 4. ЛЬГОТЫ ПО НАДБАВКАМ — § 3b EStG / § 1 SvEV
B32: Макс. необлагаемая ночная | C32: Höchstsatz Nacht steuerfrei | D32: 0.25 | E32: § 3b Abs. 1 Nr. 1 EStG
B33: Макс. необлагаемая воскресная | C33: Höchstsatz Sonntag steuerfrei | D33: 0.5 | E33: § 3b Abs. 1 Nr. 2 EStG
B34: Макс. необлагаемая праздничная | C34: Höchstsatz Feiertag steuerfrei | D34: 1.25 | E34: § 3b Abs. 1 Nr. 3 EStG; для 01.05 и 25./26.12 — 150 % (в колонке D листа «Feiertage»)
B35: Предел базы: налог | C35: Grundlohngrenze steuerfrei | D35: 50 | E35: § 3b Abs. 2 EStG
B36: Предел базы: соцвзносы | C36: Grundlohngrenze SV-frei | D36: 25 | E36: § 1 Abs. 1 Nr. 1 SvEV — твои 27 € выше, часть надбавок облагается взносами
B38: 5. ВРЕМЯ СМЕН — ЧИСЛА-ЧАСЫ (20 = 20:00, 8 = 08:00, 6,5 = 06:30)
B39: TD (Tagdienst) начало | C39: TD Beginn | D39: 8 | E39: 08:00
B40: TD (Tagdienst) конец | C40: TD Ende | D40: 20 | E40: 20:00 → 12 часов
B41: TD перерыв (часы) | C41: TD Pause | D41: 0 | E41: § 4 ArbZG при смене >9 ч требует 45 мин. Впиши 0,75 если работодатель вычитает перерыв
B42: ND (Nachtdienst) начало | C42: ND Beginn | D42: 20 | E42: 20:00
B43: ND (Nachtdienst) конец | C43: ND Ende | D43: 8 | E43: 08:00 следующего дня → 12 часов, из них 10 ночных
B44: ND перерыв (часы) | C44: ND Pause | D44: 0 | E44: § 4 ArbZG при смене >9 ч требует 45 мин
B46: 6. НАЛОГИ И СОЦВЗНОСЫ 2026
...

Sheet Feiertage
A1: ПРАЗДНИКИ / GESETZLICHE FEIERTAGE — Niedersachsen
A2: Дописывать можно до строки 43. Колонка D — максимальная НЕОБЛАГАЕМАЯ надбавка по § 3b EStG.
A3: Дата | B3: Название (Feiertag) | C3: Земля | D3: §3b Höchstsatz | E3: Примечание
A4: 46023 | B4: Neujahr | C4: bundesweit | D4: 1.25
A5: 46115 | B5: Karfreitag | C5: bundesweit | D5: 1.25
A6: 46118 | B6: Ostermontag | C6: bundesweit | D6: 1.25
A7: 46143 | B7: Tag der Arbeit | C7: bundesweit | D7: 1.5 | E7: § 3b Abs. 3 Nr. 3 — до 150 %
A8: 46156 | B8: Christi Himmelfahrt | C8: bundesweit | D8: 1.25
A9: 46167 | B9: Pfingstmontag | C9: bundesweit | D9: 1.25
A10: 46298 | B10: Tag der Deutschen Einheit | C10: bundesweit | D10: 1.25
A11: 46326 | B11: Reformationstag | C11: Niedersachsen | D11: 1.25
A12: 46381 | B12: 1. Weihnachtstag | C12: bundesweit | D12: 1.5 | E12: § 3b Abs. 3 Nr. 3 — до 150 %
A13: 46382 | B13: 2. Weihnachtstag | C13: bundesweit | D13: 1.5 | E13: § 3b Abs. 3 Nr. 3 — до 150 %
A14: 46388 | B14: Neujahr | C14: bundesweit | D14: 1.25
A15: 46472 | B15: Karfreitag | C15: bundesweit | D15: 1.25
A16: 46475 | B16: Ostermontag | C16: bundesweit | D16: 1.25
A17: 46508 | B17: Tag der Arbeit | C17: bundesweit | D17: 1.5 | E17: суббота
A18: 46513 | B18: Christi Himmelfahrt | C18: bundesweit | D18: 1.25
A19: 46524 | B19: Pfingstmontag | C19: bundesweit | D19: 1.25
A20: 46663 | B20: Tag der Deutschen Einheit | C20: bundesweit | D20: 1.25 | E20: воскресенье
A21: 46691 | B21: Reformationstag | C21: Niedersachsen | D21: 1.25 | E21: воскресенье
A22: 46746 | B22: 1. Weihnachtstag | C22: bundesweit | D22: 1.5 | E22: суббота
A23: 46747 | B23: 2. Weihnachtstag | C23: bundesweit | D23: 1.5 | E23: воскресенье
A46: НЕ праздники, но льгота по § 3b EStG:
A47: · 24.12 с 14:00 — до 150 % необлагаемо
A48: · 31.12 с 14:00 — до 125 % необлагаемо
A49: · ночь 00:00–04:00, если смена начата до полуночи — до 40 % необлагаемо (§ 3b Abs. 3 Nr. 1)
A50: · договор Constantia платит за эти часы обычные ставки — льгота касается только налога, не суммы выплаты

Sheet Dienstplan
A1: ГРАФИК И РАСЧЁТ ЧАСОВ / DIENSTPLAN
A2: ND = Nachtdienst 20:00–08:00 · TD = Tagdienst 08:00–20:00 · FREI = выходной · «x» = eingesprungen · статус: Arbeit / Urlaub / Krank / Fortbildung · FZA: j = праздник с отгулом, n = без отгула. Время — числа-часы (20 = 20:00). Смена относится к дню, в который НАЧАЛАСЬ.
A4: Дата Datum | B4: День | C4: Праздник Feiertag | D4: Смена ND/TD/FREI | E4: Статус Status | F4: Sprn | G4: FZA | H4: Начало час | I4: Конец час | J4: Пауза ч | K4: Длит. ч | L4: Часы оплач. | M4: Ночь ч | N4: Воскр. ч | O4: Праздн. ч | P4: Обычн. ч | Q4: Надбавка € | R4: из них без налога | S4: из них без взносов | T4: Отдых до смены ч | U4: Предупреждение (ArbZG)
A5: =IF(1>Настройки!$D$6,"",DATE(Настройки!$D$4,Настройки!$D$5,1)) | B5: =IF($A5="","",CHOOSE(WEEKDAY($A5,2),"Пн","Вт","Ср","Чт","Пт","Сб","Вс")) | C5: =IF($A5="","",IFERROR(INDEX(Feiertage!$B$4:$B$43,MATCH($A5,Feiertage!$A$4:$A$43,0)),"")) | D5: TD | E5: Arbeit | H5: =IF($D5="ND",Настройки!$D$42,IF($D5="TD",Настройки!$D$39,"")) | I5: =IF($D5="ND",Настройки!$D$43,IF($D5="TD",Настройки!$D$40,"")) | J5: =IF($D5="ND",Настройки!$D$44,IF($D5="TD",Настройки!$D$41,"")) | K5: =IF($H5="","",$I5-$H5+IF($I5<=$H5,24,0)) | L5: =IF($K5="","",MAX(0,$K5-$J5)) | M5: =($AF5+$AG5)*$Y5 | N5: =($Z5*$AH5+$AA5*$AI5)*$Y5 | O5: =($AB5*$AH5+$AC5*$AI5)*$Y5 | P5: =IF($L5="","",MAX(0,$L5-$O5-$AL5-$AM5)) | Q5: =ROUND(Настройки!$D$10*($AK5*$AN5+$AJ5*MAX($AN5,Настройки!$D$26)+$AL5*Настройки!$D$26+$AM5*Настройки!$D$23),2) | R5: =IF($E5<>"Arbeit",0,ROUND(MIN(Настройки!$D$10,Настройки!$D$35)*($AK5*MIN($AN5,$AO5)+$AJ5*MIN(MAX($AN5,Настройки!$D$26),$AO5)+$AL5*MIN(Настройки!$D$26,Настройки!$D$33)+$AM5*MIN(Настройки!$D$23,Настройки!$D$32)),2)) | S5: =IF($E5<>"Arbeit",0,ROUND(MIN(Настройки!$D$10,Настройки!$D$36)*($AK5*MIN($AN5,$AO5)+$AJ5*MIN(MAX($AN5,Настройки!$D$26),$AO5)+$AL5*MIN(Настройки!$D$26,Настройки!$D$33)+$AM5*MIN(Настройки!$D$23,Настройки!$D$32)),2)) | U5: =IF($L5="","",TRIM(IF($L5>10,"смена >10 ч (§ 3 / § 6 ArbZG) ","")&IF(AND($T5<>"",$T5<11),"отдых <11 ч (§ 5 ArbZG) ","")&IF(AND($L5>9,$J5<0.75),"перерыв <45 мин (§ 4 ArbZG) ","")&IF(AND($L5>6,$L5<=9,$J5<0.5),"перерыв <30 мин (§ 4 ArbZG)",""))) | W5: =IF($H5="","",$H5) | X5: =IF($H5="","",$I5+IF($I5<=$H5,24,0)) | Y5: =IF(OR($K5="",$K5=0),0,$L5/$K5) | Z5: =IF($A5="",0,IF(WEEKDAY($A5,2)=7,1,0)) | AA5: =IF($A5="",0,IF(WEEKDAY($A5+1,2)=7,1,0)) | AB5: =IF($A5="",0,MIN(1,COUNTIF(Feiertage!$A$4:$A$43,$A5))) | AC5: =IF($A5="",0,MIN(1,COUNTIF(Feiertage!$A$4:$A$43,$A5+1))) | AD5: =IFERROR(INDEX(Feiertage!$D$4:$D$43,MATCH($A5,Feiertage!$A$4:$A$43,0)),Настройки!$D$34) | AE5: =IFERROR(INDEX(Feiertage!$D$4:$D$43,MATCH($A5+1,Feiertage!$A$4:$A$43,0)),Настройки!$D$34) | AF5: =IF($W5="",0,MAX(0,MIN($X5,Настройки!$D$25)-MAX($W5,0))+MAX(0,MIN($X5,24)-MAX($W5,Настройки!$D$24))) | AG5: =IF($W5="",0,MAX(0,MIN($X5,24+Настройки!$D$25)-MAX($W5,24))) | AH5: =IF($W5="",0,MAX(0,MIN($X5,24)-MAX($W5,0))) | AI5: =IF($W5="",0,MAX(0,MIN($X5,48)-MAX($W5,24))) | AJ5: =($Z5*$AB5*$AH5+$AA5*$AC5*$AI5)*$Y5 | AK5: =$O5-$AJ5 | AL5: =$N5-$AJ5 | AM5: =$M5-(MAX($Z5,$AB5)*$AF5+MAX($AA5,$AC5)*$AG5)*$Y5 | AN5: =IF($G5="j",Настройки!$D$27,IF($G5="n",Настройки!$D$28,IF(Настройки!$D$29="mit FZA",Настройки!$D$27,Настройки!$D$28))) | AO5: =IF($O5=0,Настройки!$D$34,($AB5*$AH5*$AD5+$AC5*$AI5*$AE5)*$Y5/$O5)
A6: =IF(2>Настройки!$D$6,"",DATE(Настройки!$D$4,Настройки!$D$5,2)) | B6: =IF($A6="","",CHOOSE(WEEKDAY($A6,2),"Пн","Вт","Ср","Чт","Пт","Сб","Вс")) | C6: =IF($A6="","",IFERROR(INDEX(Feiertage!$B$4:$B$43,MATCH($A6,Feiertage!$A$4:$A$43,0)),"")) | D6: TD | E6: Arbeit | H6: =IF($D6="ND",Настройки!$D$42,IF($D6="TD",Настройки!$D$39,"")) | I6: =IF($D6="ND",Настройки!$D$43,IF($D6="TD",Настройки!$D$40,"")) | J6: =IF($D6="ND",Настройки!$D$44,IF($D6="TD",Настройки!$D$41,"")) | K6: =IF($H6="","",$I6-$H6+IF($I6<=$H6,24,0)) | L6: =IF($K6="","",MAX(0,$K6-$J6)) | M6: =($AF6+$AG6)*$Y6 | N6: =($Z6*$AH6+$AA6*$AI6)*$Y6 | O6: =($AB6*$AH6+$AC6*$AI6)*$Y6 | P6: =IF($L6="","",MAX(0,$L6-$O6-$AL6-$AM6)) | Q6: =ROUND(Настройки!$D$10*($AK6*$AN6+$AJ6*MAX($AN6,Настройки!$D$26)+$AL6*Настройки!$D$26+$AM6*Настройки!$D$23),2) | R6: =IF($E6<>"Arbeit",0,ROUND(MIN(Настройки!$D$10,Настройки!$D$35)*($AK6*MIN($AN6,$AO6)+$AJ6*MIN(MAX($AN6,Настройки!$D$26),$AO6)+$AL6*MIN(Настройки!$D$26,Настройки!$D$33)+$AM6*MIN(Настройки!$D$23,Настройки!$D$32)),2)) | S6: =IF($E6<>"Arbeit",0,ROUND(MIN(Настройки!$D$10,Настройки!$D$36)*($AK6*MIN($AN6,$AO6)+$AJ6*MIN(MAX($AN6,Настройки!$D$26),$AO6)+$AL6*MIN(Настройки!$D$26,Настройки!$D$33)+$AM6*MIN(Настройки!$D$23,Настройки!$D$32)),2)) | T6: =IF(OR($W6="",$W5=""),"",24+$W6-$X5) | U6: =IF($L6="","",TRIM(IF($L6>10,"смена >10 ч (§ 3 / § 6 ArbZG) ","")&IF(AND($T6<>"",$T6<11),"отдых <11 ч (§ 5 ArbZG) ","")&IF(AND($L6>9,$J6<0.75),"перерыв <45 мин (§ 4 ArbZG) ","")&IF(AND($L6>6,$L6<=9,$J6<0.5),"перерыв <30 мин (§ 4 ArbZG)",""))) | W6: =IF($H6="","",$H6) | X6: =IF($H6="","",$I6+IF($I6<=$H6,24,0)) | Y6: =IF(OR($K6="",$K6=0),0,$L6/$K6) | Z6: =IF($A6="",0,IF(WEEKDAY($A6,2)=7,1,0)) | AA6: =IF($A6="",0,IF(WEEKDAY($A6+1,2)=7,1,0)) | AB6: =IF($A6="",0,MIN(1,COUNTIF(Feiertage!$A$4:$A$43,$A6))) | AC6: =IF($A6="",0,MIN(1,COUNTIF(Feiertage!$A$4:$A$43,$A6+1))) | AD6: =IFERROR(INDEX(Feiertage!$D$4:$D$43,MATCH($A6,Feiertage!$A$4:$A$43,0)),Настройки!$D$34) | AE6: =IFERROR(INDEX(Feiertage!$D$4:$D$43,MATCH($A6+1,Feiertage!$A$4:$A$43,0)),Настройки!$D$34) | AF6: =IF($W6="",0,MAX(0,MIN($X6,Настройки!$D$25)-MAX($W6,0))+MAX(0,MIN($X6,24)-MAX($W6,Настройки!$D$24))) | AG6: =IF($W6="",0,MAX(0,MIN($X6,24+Настройки!$D$25)-MAX($W6,24))) | AH6: =IF($W6="",0,MAX(0,MIN($X6,24)-MAX($W6,0))) | AI6: =IF($W6="",0,MAX(0,MIN($X6,48)-MAX($W6,24))) | AJ6: =($Z6*$AB6*$AH6+$AA6*$AC6*$AI6)*$Y6 | AK6: =$O6-$AJ6 | AL6: =$N6-$AJ6 | AM6: =$M6-(MAX($Z6,$AB6)*$AF6+MAX($AA6,$AC6)*$AG6)*$Y6 | AN6: =IF($G6="j",Настройки!$D$27,IF($G6="n",Настройки!$D$28,IF(Настройки!$D$29="mit FZA",Настройки!$D$27,Настройки!$D$28))) | AO6: =IF($O6=0,Настройки!$D$34,($AB6*$AH6*$AD6+$AC6*$AI6*$AE6)*$Y6/$O6)
A7: =IF(3>Настройки!$D$6,"",DATE(Настройки!$D$4,Настройки!$D$5,3)) | B7: =IF($A7="","",CHOOSE(WEEKDAY($A7,2),"Пн","Вт","Ср","Чт","Пт","Сб","Вс")) | C7: =IF($A7="","",IFERROR(INDEX(Feiertage!$B$4:$B$43,MATCH($A7,Feiertage!$A$4:$A$43,0)),"")) | D7: FREI | H7: =IF($D7="ND",Настройки!$D$42,IF($D7="TD",Настройки!$D$39,"")) | I7: =IF($D7="ND",Настройки!$D$43,IF($D7="TD",Настройки!$D$40,"")) | J7: =IF($D7="ND",Настройки!$D$44,IF($D7="TD",Настройки!$D$41,"")) | K7: =IF($H7="","",$I7-$H7+IF($I7<=$H7,24,0)) | L7: =IF($K7="","",MAX(0,$K7-$J7)) | M7: =($AF7+$AG7)*$Y7 | N7: =($Z7*$AH7+$AA7*$AI7)*$Y7 | O7: =($AB7*$AH7+$AC7*$AI7)*$Y7 | P7: =IF($L7="","",MAX(0,$L7-$O7-$AL7-$AM7)) | Q7: =ROUND(Настройки!$D$10*($AK7*$AN7+$AJ7*MAX($AN7,Настройки!$D$26)+$AL7*Настройки!$D$26+$AM7*Настройки!$D$23),2) | R7: =IF($E7<>"Arbeit",0,ROUND(MIN(Настройки!$D$10,Настройки!$D$35)*($AK7*MIN($AN7,$AO7)+$AJ7*MIN(MAX($AN7,Настройки!$D$26),$AO7)+$AL7*MIN(Настройки!$D$26,Настройки!$D$33)+$AM7*MIN(Настройки!$D$23,Настройки!$D$32)),2)) | S7: =IF($E7<>"Arbeit",0,ROUND(MIN(Настройки!$D$10,Настройки!$D$36)*($AK7*MIN($AN7,$AO7)+$AJ7*MIN(MAX($AN7,Настройки!$D$26),$AO7)+$AL7*MIN(Настройки!$D$26,Настройки!$D$33)+$AM7*MIN(Настройки!$D$23,Настройки!$D$32)),2)) | T7: =IF(OR($W7="",$W6=""),"",24+$W7-$X6) | U7: =IF($L7="","",TRIM(IF($L7>10,"смена >10 ч (§ 3 / § 6 ArbZG) ","")&IF(AND($T7<>"",$T7<11),"отдых <11 ч (§ 5 ArbZG) ","")&IF(AND($L7>9,$J7<0.75),"перерыв <45 мин (§ 4 ArbZG) ","")&IF(AND($L7>6,$L7<=9,$J7<0.5),"перерыв <30 мин (§ 4 ArbZG)",""))) | W7: =IF($H7="","",$H7) | X7: =IF($H7="","",$I7+IF($I7<=$H7,24,0)) | Y7: =IF(OR($K7="",$K7=0),0,$L7/$K7) | Z7: =IF($A7="",0,IF(WEEKDAY($A7,2)=7,1,0)) | AA7: =IF($A7="",0,IF(WEEKDAY($A7+1,2)=7,1,0)) | AB7: =IF($A7="",0,MIN(1,COUNTIF(Feiertage!$A$4:$A$43,$A7))) | AC7: =IF($A7="",0,MIN(1,COUNTIF(Feiertage!$A$4:$A$43,$A7+1))) | AD7: =IFERROR(INDEX(Feiertage!$D$4:$D$43,MATCH($A7,Feiertage!$A$4:$A$43,0)),Настройки!$D$34) | AE7: =IFERROR(INDEX(Feiertage!$D$4:$D$43,MATCH($A7+1,Feiertage!$A$4:$A$43,0)),Настройки!$D$34) | AF7: =IF($W7="",0,MAX(0,MIN($X7,Настройки!$D$25)-MAX($W7,0))+MAX(0,MIN($X7,24)-MAX($W7,Настройки!$D$24))) | AG7: =IF($W7="",0,MAX(0,MIN($X7,24+Настройки!$D$25)-MAX($W7,24))) | AH7: =IF($W7="",0,MAX(0,MIN($X7,24)-MAX($W7,0))) | AI7: =IF($W7="",0,MAX(0,MIN($X7,48)-MAX($W7,24))) | AJ7: =($Z7*$AB7*$AH7+$AA7*$AC7*$AI7)*$Y7 | AK7: =$O7-$AJ7 | AL7: =$N7-$AJ7 | AM7: =$M7-(MAX($Z7,$AB7)*$AF7+MAX($AA7,$AC7)*$AG7)*$Y7 | AN7: =IF($G7="j",Настройки!$D$27,IF($G7="n",Настройки!$D$28,IF(Настройки!$D$29="mit FZA",Настройки!$D$27,Настройки!$D$28))) | AO7: =IF($O7=0,Настройки!$D$34,($AB7*$AH7*$AD7+$AC7*$AI7*$AE7)*$Y7/$O7)
A8: =IF(4>Настройки!$D$6,"",DATE(Настройки!$D$4,Настройки!$D$5,4)) | B8: =IF($A8="","",CHOOSE(WEEKDAY($A8,2),"Пн","Вт","Ср","Чт","Пт","Сб","Вс")) | C8: =IF($A8="","",IFERROR(INDEX(Feiertage!$B$4:$B$43,MATCH($A8,Feiertage!$A$4:$A$43,0)),"")) | D8: ND | E8: Arbeit | H8: =IF($D8="ND",Настройки!$D$42,IF($D8="TD",Настройки!$D$39,"")) | I8: =IF($D8="ND",Настройки!$D$43,IF($D8="TD",Настройки!$D$40,"")) | J8: =IF($D8="ND",Настройки!$D$44,IF($D8="TD",Настройки!$D$41,"")) | K8: =IF($H8="","",$I8-$H8+IF($I8<=$H8,24,0)) | L8: =IF($K8="","",MAX(0,$K8-$J8)) | M8: =($AF8+$AG8)*$Y8 | N8: =($Z8*$AH8+$AA8*$AI8)*$Y8 | O8: =($AB8*$AH8+$AC8*$AI8)*$Y8 | P8: =IF($L8="","",MAX(0,$L8-$O8-$AL8-$AM8)) | Q8: =ROUND(Настройки!$D$10*($AK8*$AN8+$AJ8*MAX($AN8,Настройки!$D$26)+$AL8*Настройки!$D$26+$AM8*Настройки!$D$23),2) | R8: =IF($E8<>"Arbeit",0,ROUND(MIN(Настройки!$D$10,Настройки!$D$35)*($AK8*MIN($AN8,$AO8)+$AJ8*MIN(MAX($AN8,Настройки!$D$26),$AO8)+$AL8*MIN(Настройки!$D$26,Настройки!$D$33)+$AM8*MIN(Настройки!$D$23,Настройки!$D$32)),2)) | S8: =IF($E8<>"Arbeit",0,ROUND(MIN(Настройки!$D$10,Настройки!$D$36)*($AK8*MIN($AN8,$AO8)+$AJ8*MIN(MAX($AN8,Настройки!$D$26),$AO8)+$AL8*MIN(Настройки!$D$26,Настройки!$D$33)+$AM8*MIN(Настройки!$D$23,Настройки!$D$32)),2)) | T8: =IF(OR($W8="",$W7=""),"",24+$W8-$X7) | U8: =IF($L8="","",TRIM(IF($L8>10,"смена >10 ч (§ 3 / § 6 ArbZG) ","")&IF(AND($T8<>"",$T8<11),"отдых <11 ч (§ 5 ArbZG) ","")&IF(AND($L8>9,$J8<0.75),"перерыв <45 мин (§ 4 ArbZG) ","")&IF(AND($L8>6,$L8<=9,$J8<0.5),"перерыв <30 мин (§ 4 ArbZG)",""))) | W8: =IF($H8="","",$H8) | X8: =IF($H8="","",$I8+IF($I8<=$H8,24,0)) | Y8: =IF(OR($K8="",$K8=0),0,$L8/$K8) | Z8: =IF($A8="",0,IF(WEEKDAY($A8,2)=7,1,0)) | AA8: =IF($A8="",0,IF(WEEKDAY($A8+1,2)=7,1,0)) | AB8: =IF($A8="",0,MIN(1,COUNTIF(Feiertage!$A$4:$A$43,$A8))) | AC8: =IF($A8="",0,MIN(1,COUNTIF(Feiertage!$A$4:$A$43,$A8+1))) | AD8: =IFERROR(INDEX(Feiertage!$D$4:$D$43,MATCH($A8,Feiertage!$A$4:$A$43,0)),Настройки!$D$34) | AE8: =IFERROR(INDEX(Feiertage!$D$4:$D$43,MATCH($A8+1,Feiertage!$A$4:$A$43,0)),Настройки!$D$34) | AF8: =IF($W8="",0,MAX(0,MIN($X8,Настройки!$D$25)-MAX($W8,0))+MAX(0,MIN($X8,24)-MAX($W8,Настройки!$D$24))) | AG8: =IF($W8="",0,MAX(0,MIN($X8,24+Настройки!$D$25)-MAX($W8,24))) | AH8: =IF($W8="",0,MAX(0,MIN($X8,24)-MAX($W8,0))) | AI8: =IF($W8="",0,MAX(0,MIN($X8,48)-MAX($W8,24))) | AJ8: =($Z8*$AB8*$AH8+$AA8*$AC8*$AI8)*$Y8 | AK8: =$O8-$AJ8 | AL8: =$N8-$AJ8 | AM8: =$M8-(MAX($Z8,$AB8)*$AF8+MAX($AA8,$AC8)*$AG8)*$Y8 | AN8: =IF($G8="j",Настройки!$D$27,IF($G8="n",Настройки!$D$28,IF(Настройки!$D$29="mit FZA",Настройки!$D$27,Настройки!$D$28))) | AO8: =IF($O8=0,Настройки!$D$34,($AB8*$AH8*$AD8+$AC8*$AI8*$AE8)*$Y8/$O8)
A9: =IF(5>Настройки!$D$6,"",DATE(Настройки!$D$4,Настройки!$D$5,5)) | B9: =IF($A9="","",CHOOSE(WEEKDAY($A9,2),"Пн","Вт","Ср","Чт","Пт","Сб","Вс")) | C9: =IF($A9="","",IFERROR(INDEX(Feiertage!$B$4:$B$43,MATCH($A9,Feiertage!$A$4:$A$43,0)),"")) | D9: ND | E9: Arbeit | H9: =IF($D9="ND",Настройки!$D$42,IF($D9="TD",Настройки!$D$39,"")) | I9: =IF($D9="ND",Настройки!$D$43,IF($D9="TD",Настройки!$D$40,"")) | J9: =IF($D9="ND",Настройки!$D$44,IF($D9="TD",Настройки!$D$41,"")) | K9: =IF($H9="","",$I9-$H9+IF($I9<=$H9,24,0)) | L9: =IF($K9="","",MAX(0,$K9-$J9)) | M9: =($AF9+$AG9)*$Y9 | N9: =($Z9*$AH9+$AA9*$AI9)*$Y9 | O9: =($AB9*$AH9+$AC9*$AI9)*$Y9 | P9: =IF($L9="","",MAX(0,$L9-$O9-$AL9-$AM9)) | Q9: =ROUND(Настройки!$D$10*($AK9*$AN9+$AJ9*MAX($AN9,Настройки!$D$26)+$AL9*Настройки!$D$26+$AM9*Настройки!$D$23),2) | R9: =IF($E9<>"Arbeit",0,ROUND(MIN(Настройки!$D$10,Настройки!$D$35)*($AK9*MIN($AN9,$AO9)+$AJ9*MIN(MAX($AN9,Настройки!$D$26),$AO9)+$AL9*MIN(Настройки!$D$26,Настройки!$D$33)+$AM9*MIN(Настройки!$D$23,Настройки!$D$32)),2)) | S9: =IF($E9<>"Arbeit",0,ROUND(MIN(Настройки!$D$10,Настройки!$D$36)*($AK9*MIN($AN9,$AO9)+$AJ9*MIN(MAX($AN9,Настройки!$D$26),$AO9)+$AL9*MIN(Настройки!$D$26,Настройки!$D$33)+$AM9*MIN(Настройки!$D$23,Настройки!$D$32)),2)) | T9: =IF(OR($W9="",$W8=""),"",24+$W9-$X8) | U9: =IF($L9="","",TRIM(IF($L9>10,"смена >10 ч (§ 3 / § 6 ArbZG) ","")&IF(AND($T9<>"",$T9<11),"отдых <11 ч (§ 5 ArbZG) ","")&IF(AND($L9>9,$J9<0.75),"перерыв <45 мин (§ 4 ArbZG) ","")&IF(AND($L9>6,$L9<=9,$J9<0.5),"перерыв <30 мин (§ 4 ArbZG)",""))) | W9: =IF($H9="","",$H9) | X9: =IF($H9="","",$I9+IF($I9<=$H9,24,0)) | Y9: =IF(OR($K9="",$K9=0),0,$L9/$K9) | Z9: =IF($A9="",0,IF(WEEKDAY($A9,2)=7,1,0)) | AA9: =IF($A9="",0,IF(WEEKDAY($A9+1,2)=7,1,0)) | AB9: =IF($A9="",0,MIN(1,COUNTIF(Feiertage!$A$4:$A$43,$A9))) | AC9: =IF($A9="",0,MIN(1,COUNTIF(Feiertage!$A$4:$A$43,$A9+1))) | AD9: =IFERROR(INDEX(Feiertage!$D$4:$D$43,MATCH($A9,Feiertage!$A$4:$A$43,0)),Настройки!$D$34) | AE9: =IFERROR(INDEX(Feiertage!$D$4:$D$43,MATCH($A9+1,Feiertage!$A$4:$A$43,0)),Настройки!$D$34) | AF9: =IF($W9="",0,MAX(0,MIN($X9,Настройки!$D$25)-MAX($W9,0))+MAX(0,MIN($X9,24)-MAX($W9,Настройки!$D$24))) | AG9: =IF($W9="",0,MAX(0,MIN($X9,24+Настройки!$D$25)-MAX($W9,24))) | AH9: =IF($W9="",0,MAX(0,MIN($X9,24)-MAX($W9,0))) | AI9: =IF($W9="",0,MAX(0,MIN($X9,48)-MAX($W9,24))) | AJ9: =($Z9*$AB9*$AH9+$AA9*$AC9*$AI9)*$Y9 | AK9: =$O9-$AJ9 | AL9: =$N9-$AJ9 | AM9: =$M9-(MAX($Z9,$AB9)*$AF9+MAX($AA9,$AC9)*$AG9)*$Y9 | AN9: =IF($G9="j",Настройки!$D$27,IF($G9="n",Настройки!$D$28,IF(Настройки!$D$29="mit FZA",Настройки!$D$27,Настройки!$D$28))) | AO9: =IF($O9=0,Настройки!$D$34,($AB9*$AH9*$AD9+$AC9*$AI9*$AE9)*$Y9/$O9)
A10: =IF(6>Настройки!$D$6,"",DATE(Настройки!$D$4,Настройки!$D$5,6)) | B10: =IF($A10="","",CHOOSE(WEEKDAY($A10,2),"Пн","Вт","Ср","Чт","Пт","Сб","Вс")) | C10: =IF($A10="","",IFERROR(INDEX(Feiertage!$B$4:$B$43,MATCH($A10,Feiertage!$A$4:$A$43,0)),"")) | D10: ND | E10: Arbeit | H10: =IF($D10="ND",Настройки!$D$42,IF($D10="TD",Настройки!$D$39,"")) | I10: =IF($D10="ND",Настройки!$D$43,IF($D10="TD",Настройки!$D$40,"")) | J10: =IF($D10="ND",Настройки!$D$44,IF($D10="TD",Настройки!$D$41,"")) | K10: =IF($H10="","",$I10-$H10+IF($I10<=$H10,24,0)) | L10: =IF($K10="","",MAX(0,$K10-$J10)) | M10: =($AF10+$AG10)*$Y10 | N10: =($Z10*$AH10+$AA10*$AI10)*$Y10 | O10: =($AB10*$AH10+$AC10*$AI10)*$Y10 | P10: =IF($L10="","",MAX(0,$L10-$O10-$AL10-$AM10)) | Q10: =ROUND(Настройки!$D$10*($AK10*$AN10+$AJ10*MAX($AN10,Настройки!$D$26)+$AL10*Настройки!$D$26+$AM10*Настройки!$D$23),2) | R10: =IF($E10<>"Arbeit",0,ROUND(MIN(Настройки!$D$10,Настройки!$D$35)*($AK10*MIN($AN10,$AO10)+$AJ10*MIN(MAX($AN10,Настройки!$D$26),$AO10)+$AL10*MIN(Настройки!$D$26,Настройки!$D$33)+$AM10*MIN(Настройки!$D$23,Настройки!$D$32)),2)) | S10: =IF($E10<>"Arbeit",0,ROUND(MIN(Настройки!$D$10,Настройки!$D$36)*($AK10*MIN($AN10,$AO10)+$AJ10*MIN(MAX($AN10,Настройки!$D$26),$AO10)+$AL10*MIN(Настройки!$D$26,Настройки!$D$33)+$AM10*MIN(Настройки!$D$23,Настройки!$D$32)),2)) | T10: =IF(OR($W10="",$W9=""),"",24+$W10-$X9) | U10: =IF($L10="","",TRIM(IF($L10>10,"смена >10 ч (§ 3 / § 6 ArbZG) ","")&IF(AND($T10<>"",$T10<11),"отдых <11 ч (§ 5 ArbZG) ","")&IF(AND($L10>9,$J10<0.75),"перерыв <45 мин (§ 4 ArbZG) ","")&IF(AND($L10>6,$L10<=9,$J10<0.5),"перерыв <30 мин (§ 4 ArbZG)",""))) | W10: =IF($H10="","",$H10) | X10: =IF($H10="","",$I10+IF($I10<=$H10,24,0)) | Y10: =IF(OR($K10="",$K10=0),0,$L10/$K10) | Z10: =IF($A10="",0,IF(WEEKDAY($A10,2)=7,1,0)) | AA10: =IF($A10="",0,IF(WEEKDAY($A10+1,2)=7,1,0)) | AB10: =IF($A10="",0,MIN(1,COUNTIF(Feiertage!$A$4:$A$43,$A10))) | AC10: =IF($A10="",0,MIN(1,COUNTIF(Feiertage!$A$4:$A$43,$A10+1))) | AD10: =IFERROR(INDEX(Feiertage!$D$4:$D$43,MATCH($A10,Feiertage!$A$4:$A$43,0)),Настройки!$D$34) | AE10: =IFERROR(INDEX(Feiertage!$D$4:$D$43,MATCH($A10+1,Feiertage!$A$4:$A$43,0)),Настройки!$D$34) | AF10: =IF($W10="",0,MAX(0,MIN($X10,Настройки!$D$25)-MAX($W10,0))+MAX(0,MIN($X10,24)-MAX($W10,Настройки!$D$24))) | AG10: =IF($W10="",0,MAX(0,MIN($X10,24+Настройки!$D$25)-MAX($W10,24))) | AH10: =IF($W10="",0,MAX(0,MIN($X10,24)-MAX($W10,0))) | AI10: =IF($W10="",0,MAX(0,MIN($X10,48)-MAX($W10,24))) | AJ10: =($Z10*$AB10*$AH10+$AA10*$AC10*$AI10)*$Y10 | AK10: =$O10-$AJ10 | AL10: =$N10-$AJ10 | AM10: =$M10-(MAX($Z10,$AB10)*$AF10+MAX($AA10,$AC10)*$AG10)*$Y10 | AN10: =IF($G10="j",Настройки!$D$27,IF($G10="n",Настройки!$D$28,IF(Настройки!$D$29="mit FZA",Настройки!$D$27,Настройки!$D$28))) | AO10: =IF($O10=0,Настройки!$D$34,($AB10*$AH10*$AD10+$AC10*$AI10*$AE10)*$Y10/$O10)
A11: =IF(7>Настройки!$D$6,"",DATE(Настройки!$D$4,Настройки!$D$5,7)) | B11: =IF($A11="","",CHOOSE(WEEKDAY($A11,2),"Пн","Вт","Ср","Чт","Пт","Сб","Вс")) | C11: =IF($A11="","",IFERROR(INDEX(Feiertage!$B$4:$B$43,MATCH($A11,Feiertage!$A$4:$A$43,0)),"")) | D11: FREI | H11: =IF($D11="ND",Настройки!$D$42,IF($D11="TD",Настройки!$D$39,"")) | I11: =IF($D11="ND",Настройки!$D$43,IF($D11="TD",Настройки!$D$40,"")) | J11: =IF($D11="ND",Настройки!$D$44,IF($D11="TD",Настройки!$D$41,"")) | K11: =IF($H11="","",$I11-$H11+IF($I11<=$H11,24,0)) | L11: =IF($K11="","",MAX(0,$K11-$J11)) | M11: =($AF11+$AG11)*$Y11 | N11: =($Z11*$AH11+$AA11*$AI11)*$Y11 | O11: =($AB11*$AH11+$AC11*$AI11)*$Y11 | P11: =IF($L11="","",MAX(0,$L11-$O11-$AL11-$AM11)) | Q11: =ROUND(Настройки!$D$10*($AK11*$AN11+$AJ11*MAX($AN11,Настройки!$D$26)+$AL11*Настройки!$D$26+$AM11*Настройки!$D$23),2) | R11: =IF($E11<>"Arbeit",0,ROUND(MIN(Настройки!$D$10,Настройки!$D$35)*($AK11*MIN($AN11,$AO11)+$AJ11*MIN(MAX($AN11,Настройки!$D$26),$AO11)+$AL11*MIN(Настройки!$D$26,Настройки!$D$33)+$AM11*MIN(Настройки!$D$23,Настройки!$D$32)),2)) | S11: =IF($E11<>"Arbeit",0,ROUND(MIN(Настройки!$D$10,Настройки!$D$36)*($AK11*MIN($AN11,$AO11)+$AJ11*MIN(MAX($AN11,Настройки!$D$26),$AO11)+$AL11*MIN(Настройки!$D$26,Настройки!$D$33)+$AM11*MIN(Настройки!$D$23,Настройки!$D$32)),2)) | T11: =IF(OR($W11="",$W10=""),"",24+$W11-$X10) | U11: =IF($L11="","",TRIM(IF($L11>10,"смена >10 ч (§ 3 / § 6 ArbZG) ","")&IF(AND($T11<>"",$T11<11),"отдых <11 ч (§ 5 ArbZG) ","")&IF(AND($L11>9,$J11<0.75),"перерыв <45 мин (§ 4 ArbZG) ","")&IF(AND($L11>6,$L11<=9,$J11<0.5),"перерыв <30 мин (§ 4 ArbZG)",""))) | W11: =IF($H11="","",$H11) | X11: =IF($H11="","",$I11+IF($I11<=$H11,24,0)) | Y11: =IF(OR($K11="",$K11=0),0,$L11/$K11) | Z11: =IF($A11="",0,IF(WEEKDAY($A11,2)=7,1,0)) | AA11: =IF($A11="",0,IF(WEEKDAY($A11+1,2)=7,1,0)) | AB11: =IF($A11="",0,MIN(1,COUNTIF(Feiertage!$A$4:$A$43,$A11))) | AC11: =IF($A11="",0,MIN(1,COUNTIF(Feiertage!$A$4:$A$43,$A11+1))) | AD11: =IFERROR(INDEX(Feiertage!$D$4:$D$43,MATCH($A11,Feiertage!$A$4:$A$43,0)),Настройки!$D$34) | AE11: =IFERROR(INDEX(Feiertage!$D$4:$D$43,MATCH($A11+1,Feiertage!$A$4:$A$43,0)),Настройки!$D$34) | AF11: =IF($W11="",0,MAX(0,MIN($X11,Настройки!$D$25)-MAX($W11,0))+MAX(0,MIN($X11,24)-MAX($W11,Настройки!$D$24))) | AG11: =IF($W11="",0,MAX(0,MIN($X11,24+Настройки!$D$25)-MAX($W11,24))) | AH11: =IF($W11="",0,MAX(0,MIN($X11,24)-MAX($W11,0))) | AI11: =IF($W11="",0,MAX(0,MIN($X11,48)-MAX($W11,24))) | AJ11: =($Z11*$AB11*$AH11+$AA11*$AC11*$AI11)*$Y11 | AK11: =$O11-$AJ11 | AL11: =$N11-$AJ11 | AM11: =$M11-(MAX($Z11,$AB11)*$AF11+MAX($AA11,$AC11)*$AG11)*$Y11 | AN11: =IF($G11="j",Настройки!$D$27,IF($G11="n",Настройки!$D$28,IF(Настройки!$D$29="mit FZA",Настройки!$D$27,Настройки!$D$28))) | AO11: =IF($O11=0,Настройки!$D$34,($AB11*$AH11*$AD11+$AC11*$AI11*$AE11)*$Y11/$O11)
A12: =IF(8>Настройки!$D$6,"",DATE(Настройки!$D$4,Настройки!$D$5,8)) | B12: =IF($A12="","",CHOOSE(WEEKDAY($A12,2),"Пн","Вт","Ср","Чт","Пт","Сб","Вс")) | C12: =IF($A12="","",IFERROR(INDEX(Feiertage!$B$4:$B$43,MATCH($A12,Feiertage!$A$4:$A$43,0)),"")) | D12: FREI | H12: =IF($D12="ND",Настройки!$D$42,IF($D12="TD",Настройки!$D$39,"")) | I12: =IF($D12="ND",Настройки!$D$43,IF($D12="TD",Настройки!$D$40,"")) | J12: =IF($D12="ND",Настройки!$D$44,IF($D12="TD",Настройки!$D$41,"")) | K12: =IF($H12="","",$I12-$H12+IF($I12<=$H12,24,0)) | L12: =IF($K12="","",MAX(0,$K12-$J12)) | M12: =($AF12+$AG12)*$Y12 | N12: =($Z12*$AH12+$AA12*$AI12)*$Y12 | O12: =($AB12*$AH12+$AC12*$AI12)*$Y12 | P12: =IF($L12="","",MAX(0,$L12-$O12-$AL12-$AM12)) | Q12: =ROUND(Настройки!$D$10*($AK12*$AN12+$AJ12*MAX($AN12,Настройки!$D$26)+$AL12*Настройки!$D$26+$AM12*Настройки!$D$23),2) | R12: =IF($E12<>"Arbeit",0,ROUND(MIN(Настройки!$D$10,Настройки!$D$35)*($AK12*MIN($AN12,$AO12)+$AJ12*MIN(MAX($AN12,Настройки!$D$26),$AO12)+$AL12*MIN(Настройки!$D$26,Настройки!$D$33)+$AM12*MIN(Настройки!$D$23,Настройки!$D$32)),2)) | S12: =IF($E12<>"Arbeit",0,ROUND(MIN(Настройки!$D$10,Настройки!$D$36)*($AK12*MIN($AN12,$AO12)+$AJ12*MIN(MAX($AN12,Настройки!$D$26),$AO12)+$AL12*MIN(Настройки!$D$26,Настройки!$D$33)+$AM12*MIN(Настройки!$D$23,Настройки!$D$32)),2)) | T12: =IF(OR($W12="",$W11=""),"",24+$W12-$X11) | U12: =IF($L12="","",TRIM(IF($L12>10,"смена >10 ч (§ 3 / § 6 ArbZG) ","")&IF(AND($T12<>"",$T12<11),"отдых <11 ч (§ 5 ArbZG) ","")&IF(AND($L12>9,$J12<0.75),"перерыв <45 мин (§ 4 ArbZG) ","")&IF(AND($L12>6,$L12<=9,$J12<0.5),"перерыв <30 мин (§ 4 ArbZG)",""))) | W12: =IF($H12="","",$H12) | X12: =IF($H12="","",$I12+IF($I12<=$H12,24,0)) | Y12: =IF(OR($K12="",$K12=0),0,$L12/$K12) | Z12: =IF($A12="",0,IF(WEEKDAY($A12,2)=7,1,0)) | AA12: =IF($A12="",0,IF(WEEKDAY($A12+1,2)=7,1,0)) | AB12: =IF($A12="",0,MIN(1,COUNTIF(Feiertage!$A$4:$A$43,$A12))) | AC12: =IF($A12="",0,MIN(1,COUNTIF(Feiertage!$A$4:$A$43,$A12+1))) | AD12: =IFERROR(INDEX(Feiertage!$D$4:$D$43,MATCH($A12,Feiertage!$A$4:$A$43,0)),Настройки!$D$34) | AE12: =IFERROR(INDEX(Feiertage!$D$4:$D$43,MATCH($A12+1,Feiertage!$A$4:$A$43,0)),Настройки!$D$34) | AF12: =IF($W12="",0,MAX(0,MIN($X12,Настройки!$D$25)-MAX($W12,0))+MAX(0,MIN($X12,24)-MAX($W12,Настройки!$D$24))) | AG12: =IF($W12="",0,MAX(0,MIN($X12,24+Настройки!$D$25)-MAX($W12,24))) | AH12: =IF($W12="",0,MAX(0,MIN($X12,24)-MAX($W12,0))) | AI12: =IF($W12="",0,MAX(0,MIN($X12,48)-MAX($W12,24))) | AJ12: =($Z12*$AB12*$AH12+$AA12*$AC12*$AI12)*$Y12 | AK12: =$O12-$AJ12 | AL12: =$N12-$AJ12 | AM12: =$M12-(MAX($Z12,$AB12)*$AF12+MAX($AA12,$AC12)*$AG12)*$Y12 | AN12: =IF($G12="j",Настройки!$D$27,IF($G12="n",Настройки!$D$28,IF(Настройки!$D$29="mit FZA",Настройки!$D$27,Настройки!$D$28))) | AO12: =IF($O12=0,Настройки!$D$34,($AB12*$AH12*$AD12+$AC12*$AI12*$AE12)*$Y12/$O12)
A13: =IF(9>Настройки!$D$6,"",DATE(Настройки!$D$4,Настройки!$D$5,9)) | B13: =IF($A13="","",CHOOSE(WEEKDAY($A13,2),"Пн","Вт","Ср","Чт","Пт","Сб","Вс")) | C13: =IF($A13="","",IFERROR(INDEX(Feiertage!$B$4:$B$43,MATCH($A13,Feiertage!$A$4:$A$43,0)),"")) | D13: TD | E13: Arbeit | H13: =IF($D13="ND",Настройки!$D$42,IF($D13="TD",Настройки!$D$39,"")) | I13: =IF($D13="ND",Настройки!$D$43,IF($D13="TD",Настройки!$D$40,"")) | J13: =IF($D13="ND",Настройки!$D$44,IF($D13="TD",Настройки!$D$41,"")) | K13: =IF($H13="","",$I13-$H13+IF($I13<=$H13,24,0)) | L13: =IF($K13="","",MAX(0,$K13-$J13)) | M13: =($AF13+$AG13)*$Y13 | N13: =($Z13*$AH13+$AA13*$AI13)*$Y13 | O13: =($AB13*$AH13+$AC13*$AI13)*$Y13 | P13: =IF($L13="","",MAX(0,$L13-$O13-$AL13-$AM13)) | Q13: =ROUND(Настройки!$D$10*($AK13*$AN13+$AJ13*MAX($AN13,Настройки!$D$26)+$AL13*Настройки!$D$26+$AM13*Настройки!$D$23),2) | R13: =IF($E13<>"Arbeit",0,ROUND(MIN(Настройки!$D$10,Настройки!$D$35)*($AK13*MIN($AN13,$AO13)+$AJ13*MIN(MAX($AN13,Настройки!$D$26),$AO13)+$AL13*MIN(Настройки!$D$26,Настройки!$D$33)+$AM13*MIN(Настройки!$D$23,Настройки!$D$32)),2)) | S13: =IF($E13<>"Arbeit",0,ROUND(MIN(Настройки!$D$10,Настройки!$D$36)*($AK13*MIN($AN13,$AO13)+$AJ13*MIN(MAX($AN13,Настройки!$D$26),$AO13)+$AL13*MIN(Настройки!$D$26,Настройки!$D$33)+$AM13*MIN(Настройки!$D$23,Настройки!$D$32)),2)) | T13: =IF(OR($W13="",$W12=""),"",24+$W13-$X12) | U13: =IF($L13="","",TRIM(IF($L13>10,"смена >10 ч (§ 3 / § 6 ArbZG) ","")&IF(AND($T13<>"",$T13<11),"отдых <11 ч (§ 5 ArbZG) ","")&IF(AND($L13>9,$J13<0.75),"перерыв <45 мин (§ 4 ArbZG) ","")&IF(AND($L13>6,$L13<=9,$J13<0.5),"перерыв <30 мин (§ 4 ArbZG)",""))) | W13: =IF($H13="","",$H13) | X13: =IF($H13="","",$I13+IF($I13<=$H13,24,0)) | Y13: =IF(OR($K13="",$K13=0),0,$L13/$K13) | Z13: =IF($A13="",0,IF(WEEKDAY($A13,2)=7,1,0)) | AA13: =IF($A13="",0,IF(WEEKDAY($A13+1,2)=7,1,0)) | AB13: =IF($A13="",0,MIN(1,COUNTIF(Feiertage!$A$4:$A$43,$A13))) | AC13: =IF($A13="",0,MIN(1,COUNTIF(Feiertage!$A$4:$A$43,$A13+1))) | AD13: =IFERROR(INDEX(Feiertage!$D$4:$D$43,MATCH($A13,Feiertage!$A$4:$A$43,0)),Настройки!$D$34) | AE13: =IFERROR(INDEX(Feiertage!$D$4:$D$43,MATCH($A13+1,Feiertage!$A$4:$A$43,0)),Настройки!$D$34) | AF13: =IF($W13="",0,MAX(0,MIN($X13,Настройки!$D$25)-MAX($W13,0))+MAX(0,MIN($X13,24)-MAX($W13,Настройки!$D$24))) | AG13: =IF($W13="",0,MAX(0,MIN($X13,24+Настройки!$D$25)-MAX($W13,24))) | AH13: =IF($W13="",0,MAX(0,MIN($X13,24)-MAX($W13,0))) | AI13: =IF($W13="",0,MAX(0,MIN($X13,48)-MAX($W13,24))) | AJ13: =($Z13*$AB13*$AH13+$AA13*$AC13*$AI13)*$Y13 | AK13: =$O13-$AJ13 | AL13: =$N13-$AJ13 | AM13: =$M13-(MAX($Z13,$AB13)*$AF13+MAX($AA13,$AC13)*$AG13)*$Y13 | AN13: =IF($G13="j",Настройки!$D$27,IF($G13="n",Настройки!$D$28,IF(Настройки!$D$29="mit FZA",Настройки!$D$27,Настройки!$D$28))) | AO13: =IF($O13=0,Настройки!$D$34,($AB13*$AH13*$AD13+$AC13*$AI13*$AE13)*$Y13/$O13)
A14: =IF(10>Настройки!$D$6,"",DATE(Настройки!$D$4,Настройки!$D$5,10)) | B14: =IF($A14="","",CHOOSE(WEEKDAY($A14,2),"Пн","Вт","Ср","Чт","Пт","Сб","Вс")) | C14: =IF($A14="","",IFERROR(INDEX(Feiertage!$B$4:$B$43,MATCH($A14,Feiertage!$A$4:$A$43,0)),"")) | D14: TD | E14: Arbeit | H14: =IF($D14="ND",Настройки!$D$42,IF($D14="TD",Настройки!$D$39,"")) | I14: =IF($D14="ND",Настройки!$D$43,IF($D14="TD",Настройки!$D$40,"")) | J14: =IF($D14="ND",Настройки!$D$44,IF($D14="TD",Настройки!$D$41,"")) | K14: =IF($H14="","",$I14-$H14+IF($I14<=$H14,24,0)) | L14: =IF($K14="","",MAX(0,$K14-$J14)) | M14: =($AF14+$AG14)*$Y14 | N14: =($Z14*$AH14+$AA14*$AI14)*$Y14 | O14: =($AB14*$AH14+$AC14*$AI14)*$Y14 | P14: =IF($L14="","",MAX(0,$L14-$O14-$AL14-$AM14)) | Q14: =ROUND(Настройки!$D$10*($AK14*$AN14+$AJ14*MAX($AN14,Настройки!$D$26)+$AL14*Настройки!$D$26+$AM14*Настройки!$D$23),2) | R14: =IF($E14<>"Arbeit",0,ROUND(MIN(Настройки!$D$10,Настройки!$D$35)*($AK14*MIN($AN14,$AO14)+$AJ14*MIN(MAX($AN14,Настройки!$D$26),$AO14)+$AL14*MIN(Настройки!$D$26,Настройки!$D$33)+$AM14*MIN(Настройки!$D$23,Настройки!$D$32)),2)) | S14: =IF($E14<>"Arbeit",0,ROUND(MIN(Настройки!$D$10,Настройки!$D$36)*($AK14*MIN($AN14,$AO14)+$AJ14*MIN(MAX($AN14,Настройки!$D$26),$AO14)+$AL14*MIN(Настройки!$D$26,Настройки!$D$33)+$AM14*MIN(Настройки!$D$23,Настройки!$D$32)),2)) | T14: =IF(OR($W14="",$W13=""),"",24+$W14-$X13) | U14: =IF($L14="","",TRIM(IF($L14>10,"смена >10 ч (§ 3 / § 6 ArbZG) ","")&IF(AND($T14<>"",$T14<11),"отдых <11 ч (§ 5 ArbZG) ","")&IF(AND($L14>9,$J14<0.75),"перерыв <45 мин (§ 4 ArbZG) ","")&IF(AND($L14>6,$L14<=9,$J14<0.5),"перерыв <30 мин (§ 4 ArbZG)",""))) | W14: =IF($H14="","",$H14) | X14: =IF($H14="","",$I14+IF($I14<=$H14,24,0)) | Y14: =IF(OR($K14="",$K14=0),0,$L14/$K14) | Z14: =IF($A14="",0,IF(WEEKDAY($A14,2)=7,1,0)) | AA14: =IF($A14="",0,IF(WEEKDAY($A14+1,2)=7,1,0)) | AB14: =IF($A14="",0,MIN(1,COUNTIF(Feiertage!$A$4:$A$43,$A14))) | AC14: =IF($A14="",0,MIN(1,COUNTIF(Feiertage!$A$4:$A$43,$A14+1))) | AD14: =IFERROR(INDEX(Feiertage!$D$4:$D$43,MATCH($A14,Feiertage!$A$4:$A$43,0)),Настройки!$D$34) | AE14: =IFERROR(INDEX(Feiertage!$D$4:$D$43,MATCH($A14+1,Feiertage!$A$4:$A$43,0)),Настройки!$D$34) | AF14: =IF($W14="",0,MAX(0,MIN($X14,Настройки!$D$25)-MAX($W14,0))+MAX(0,MIN($X14,24)-MAX($W14,Настройки!$D$24))) | AG14: =IF($W14="",0,MAX(0,MIN($X14,24+Настройки!$D$25)-MAX($W14,24))) | AH14: =IF($W14="",0,MAX(0,MIN($X14,24)-MAX($W14,0))) | AI14: =IF($W14="",0,MAX(0,MIN($X14,48)-MAX($W14,24))) | AJ14: =($Z14*$AB14*$AH14+$AA14*$AC14*$AI14)*$Y14 | AK14: =$O14-$AJ14 | AL14: =$N14-$AJ14 | AM14: =$M14-(MAX($Z14,$AB14)*$AF14+MAX($AA14,$AC14)*$AG14)*$Y14 | AN14: =IF($G14="j",Настройки!$D$27,IF($G14="n",Настройки!$D$28,IF(Настройки!$D$29="mit FZA",Настройки!$D$27,Настройки!$D$28))) | AO14: =IF($O14=0,Настройки!$D$34,($AB14*$AH14*$AD14+$AC14*$AI14*$AE14)*$Y14/$O14)
A15: =IF(11>Настройки!$D$6,"",DATE(Настройки!$D$4,Настройки!$D$5,11)) | B15: =IF($A15="","",CHOOSE(WEEKDAY($A15,2),"Пн","Вт","Ср","Чт","Пт","Сб","Вс")) | C15: =IF($A15="","",IFERROR(INDEX(Feiertage!$B$4:$B$43,MATCH($A15,Feiertage!$A$4:$A$43,0)),"")) | D15: TD | E15: Arbeit | H15: =IF($D15="ND",Настройки!$D$42,IF($D15="TD",Настройки!$D$39,"")) | I15: =IF($D15="ND",Настройки!$D$43,IF($D15="TD",Настройки!$D$40,"")) | J15: =IF($D15="ND",Настройки!$D$44,IF($D15="TD",Настройки!$D$41,"")) | K15: =IF($H15="","",$I15-$H15+IF($I15<=$H15,24,0)) | L15: =IF($K15="","",MAX(0,$K15-$J15)) | M15: =($AF15+$AG15)*$Y15 | N15: =($Z15*$AH15+$AA15*$AI15)*$Y15 | O15: =($AB15*$AH15+$AC15*$AI15)*$Y15 | P15: =IF($L15="","",MAX(0,$L15-$O15-$AL15-$AM15)) | Q15: =ROUND(Настройки!$D$10*($AK15*$AN15+$AJ15*MAX($AN15,Настройки!$D$26)+$AL15*Настройки!$D$26+$AM15*Настройки!$D$23),2) | R15: =IF($E15<>"Arbeit",0,ROUND(MIN(Настройки!$D$10,Настройки!$D$35)*($AK15*MIN($AN15,$AO15)+$AJ15*MIN(MAX($AN15,Настройки!$D$26),$AO15)+$AL15*MIN(Настройки!$D$26,Настройки!$D$33)+$AM15*MIN(Настройки!$D$23,Настройки!$D$32)),2)) | S15: =IF($E15<>"Arbeit",0,ROUND(MIN(Настройки!$D$10,Настройки!$D$36)*($AK15*MIN($AN15,$AO15)+$AJ15*MIN(MAX($AN15,Настройки!$D$26),$AO15)+$AL15*MIN(Настройки!$D$26,Настройки!$D$33)+$AM15*MIN(Настройки!$D$23,Настройки!$D$32)),2)) | T15: =IF(OR($W15="",$W14=""),"",24+$W15-$X14) | U15: =IF($L15="","",TRIM(IF($L15>10,"смена >10 ч (§ 3 / § 6 ArbZG) ","")&IF(AND($T15<>"",$T15<11),"отдых <11 ч (§ 5 ArbZG) ","")&IF(AND($L15>9,$J15<0.75),"перерыв <45 мин (§ 4 ArbZG) ","")&IF(AND($L15>6,$L15<=9,$J15<0.5),"перерыв <30 мин (§ 4 ArbZG)",""))) | W15: =IF($H15="","",$H15) | X15: =IF($H15="","",$I15+IF($I15<=$H15,24,0)) | Y15: =IF(OR($K15="",$K15=0),0,$L15/$K15) | Z15: =IF($A15="",0,IF(WEEKDAY($A15,2)=7,1,0)) | AA15: =IF($A15="",0,IF(WEEKDAY($A15+1,2)=7,1,0)) | AB15: =IF($A15="",0,MIN(1,COUNTIF(Feiertage!$A$4:$A$43,$A15))) | AC15: =IF($A15="",0,MIN(1,COUNTIF(Feiertage!$A$4:$A$43,$A15+1))) | AD15: =IFERROR(INDEX(Feiertage!$D$4:$D$43,MATCH($A15,Feiertage!$A$4:$A$43,0)),Настройки!$D$34) | AE15: =IFERROR(INDEX(Feiertage!$D$4:$D$43,MATCH($A15+1,Feiertage!$A$4:$A$43,0)),Настройки!$D$34) | AF15: =IF($W15="",0,MAX(0,MIN($X15,Настройки!$D$25)-MAX($W15,0))+MAX(0,MIN($X15,24)-MAX($W15,Настройки!$D$24))) | AG15: =IF($W15="",0,MAX(0,MIN($X15,24+Настройки!$D$25)-MAX($W15,24))) | AH15: =IF($W15="",0,MAX(0,MIN($X15,24)-MAX($W15,0))) | AI15: =IF($W15="",0,MAX(0,MIN($X15,48)-MAX($W15,24))) | AJ15: =($Z15*$AB15*$AH15+$AA15*$AC15*$AI15)*$Y15 | AK15: =$O15-$AJ15 | AL15: =$N15-$AJ15 | AM15: =$M15-(MAX($Z15,$AB15)*$AF15+MAX($AA15,$AC15)*$AG15)*$Y15 | AN15: =IF($G15="j",Настройки!$D$27,IF($G15="n",Настройки!$D$28,IF(Настройки!$D$29="mit FZA",Настройки!$D$27,Настройки!$D$28))) | AO15: =IF($O15=0,Настройки!$D$34,($AB15*$AH15*$AD15+$AC15*$AI15*$AE15)*$Y15/$O15)
A16: =IF(12>Настройки!$D$6,"",DATE(Настройки!$D$4,Настройки!$D$5,12)) | B16: =IF($A16="","",CHOOSE(WEEKDAY($A16,2),"Пн","Вт","Ср","Чт","Пт","Сб","Вс")) | C16: =IF($A16="","",IFERROR(INDEX(Feiertage!$B$4:$B$43,MATCH($A16,Feiertage!$A$4:$A$43,0)),"")) | D16: TD | E16: Arbeit | H16: =IF($D16="ND",Настройки!$D$42,IF($D16="TD",Настройки!$D$39,"")) | I16: =IF($D16="ND",Настройки!$D$43,IF($D16="TD",Настройки!$D$40,"")) | J16: =IF($D16="ND",Настройки!$D$44,IF($D16="TD",Настройки!$D$41,"")) | K16: =IF($H16="","",$I16-$H16+IF($I16<=$H16,24,0)) | L16: =IF($K16="","",MAX(0,$K16-$J16)) | M16: =($AF16+$AG16)*$Y16 | N16: =($Z16*$AH16+$AA16*$AI16)*$Y16 | O16: =($AB16*$AH16+$AC16*$AI16)*$Y16 | P16: =IF($L16="","",MAX(0,$L16-$O16-$AL16-$AM16)) | Q16: =ROUND(Настройки!$D$10*($AK16*$AN16+$AJ16*MAX($AN16,Настройки!$D$26)+$AL16*Настройки!$D$26+$AM16*Настройки!$D$23),2) | R16: =IF($E16<>"Arbeit",0,ROUND(MIN(Настройки!$D$10,Настройки!$D$35)*($AK16*MIN($AN16,$AO16)+$AJ16*MIN(MAX($AN16,Настройки!$D$26),$AO16)+$AL16*MIN(Настройки!$D$26,Настройки!$D$33)+$AM16*MIN(Настройки!$D$23,Настройки!$D$32)),2)) | S16: =IF($E16<>"Arbeit",0,ROUND(MIN(Настройки!$D$10,Настройки!$D$36)*($AK16*MIN($AN16,$AO16)+$AJ16*MIN(MAX($AN16,Настройки!$D$26),$AO16)+$AL16*MIN(Настройки!$D$26,Настройки!$D$33)+$AM16*MIN(Настройки!$D$23,Настройки!$D$32)),2)) | T16: =IF(OR($W16="",$W15=""),"",24+$W16-$X15) | U16: =IF($L16="","",TRIM(IF($L16>10,"смена >10 ч (§ 3 / § 6 ArbZG) ","")&IF(AND($T16<>"",$T16<11),"отдых <11 ч (§ 5 ArbZG) ","")&IF(AND($L16>9,$J16<0.75),"перерыв <45 мин (§ 4 ArbZG) ","")&IF(AND($L16>6,$L16<=9,$J16<0.5),"перерыв <30 мин (§ 4 ArbZG)",""))) | W16: =IF($H16="","",$H16) | X16: =IF($H16="","",$I16+IF($I16<=$H16,24,0)) | Y16: =IF(OR($K16="",$K16=0),0,$L16/$K16) | Z16: =IF($A16="",0,IF(WEEKDAY($A16,2)=7,1,0)) | AA16: =IF($A16="",0,IF(WEEKDAY($A16+1,2)=7,1,0)) | AB16: =IF($A16="",0,MIN(1,COUNTIF(Feiertage!$A$4:$A$43,$A16))) | AC16: =IF($A16="",0,MIN(1,COUNTIF(Feiertage!$A$4:$A$43,$A16+1))) | AD16: =IFERROR(INDEX(Feiertage!$D$4:$D$43,MATCH($A16,Feiertage!$A$4:$A$43,0)),Настройки!$D$34) | AE16: =IFERROR(INDEX(Feiertage!$D$4:$D$43,MATCH($A16+1,Feiertage!$A$4:$A$43,0)),Настройки!$D$34) | AF16: =IF($W16="",0,MAX(0,MIN($X16,Настройки!$D$25)-MAX($W16,0))+MAX(0,MIN($X16,24)-MAX($W16,Настройки!$D$24))) | AG16: =IF($W16="",0,MAX(0,MIN($X16,24+Настройки!$D$25)-MAX($W16,24))) | AH16: =IF($W16="",0,MAX(0,MIN($X16,24)-MAX($W16,0))) | AI16: =IF($W16="",0,MAX(0,MIN($X16,48)-MAX($W16,24))) | AJ16: =($Z16*$AB16*$AH16+$AA16*$AC16*$AI16)*$Y16 | AK16: =$O16-$AJ16 | AL16: =$N16-$AJ16 | AM16: =$M16-(MAX($Z16,$AB16)*$AF16+MAX($AA16,$AC16)*$AG16)*$Y16 | AN16: =IF($G16="j",Настройки!$D$27,IF($G16="n",Настройки!$D$28,IF(Настройки!$D$29="mit FZA",Настройки!$D$27,Настройки!$D$28))) | AO16: =IF($O16=0,Настройки!$D$34,($AB16*$AH16*$AD16+$AC16*$AI16*$AE16)*$Y16/$O16)
A17: =IF(13>Настройки!$D$6,"",DATE(Настройки!$D$4,Настройки!$D$5,13)) | B17: =IF($A17="","",CHOOSE(WEEKDAY($A17,2),"Пн","Вт","Ср","Чт","Пт","Сб","Вс")) | C17: =IF($A17="","",IFERROR(INDEX(Feiertage!$B$4:$B$43,MATCH($A17,Feiertage!$A$4:$A$43,0)),"")) | D17: TD | E17: Arbeit | H17: =IF($D17="ND",Настройки!$D$42,IF($D17="TD",Настройки!$D$39,"")) | I17: =IF($D17="ND",Настройки!$D$43,IF($D17="TD",Настройки!$D$40,"")) | J17: =IF($D17="ND",Настройки!$D$44,IF($D17="TD",Настройки!$D$41,"")) | K17: =IF($H17="","",$I17-$H17+IF($I17<=$H17,24,0)) | L17: =IF($K17="","",MAX(0,$K17-$J17)) | M17: =($AF17+$AG17)*$Y17 | N17: =($Z17*$AH17+$AA17*$AI17)*$Y17 | O17: =($AB17*$AH17+$AC17*$AI17)*$Y17 | P17: =IF($L17="","",MAX(0,$L17-$O17-$AL17-$AM17)) | Q17: =ROUND(Настройки!$D$10*($AK17*$AN17+$AJ17*MAX($AN17,Настройки!$D$26)+$AL17*Настройки!$D$26+$AM17*Настройки!$D$23),2) | R17: =IF($E17<>"Arbeit",0,ROUND(MIN(Настройки!$D$10,Настройки!$D$35)*($AK17*MIN($AN17,$AO17)+$AJ17*MIN(MAX($AN17,Настройки!$D$26),$AO17)+$AL17*MIN(Настройки!$D$26,Настройки!$D$33)+$AM17*MIN(Настройки!$D$23,Настройки!$D$32)),2)) | S17: =IF($E17<>"Arbeit",0,ROUND(MIN(Настройки!$D$10,Настройки!$D$36)*($AK17*MIN($AN17,$AO17)+$AJ17*MIN(MAX($AN17,Настройки!$D$26),$AO17)+$AL17*MIN(Настройки!$D$26,Настройки!$D$33)+$AM17*MIN(Настройки!$D$23,Настройки!$D$32)),2)) | T17: =IF(OR($W17="",$W16=""),"",24+$W17-$X16) | U17: =IF($L17="","",TRIM(IF($L17>10,"смена >10 ч (§ 3 / § 6 ArbZG) ","")&IF(AND($T17<>"",$T17<11),"отдых <11 ч (§ 5 ArbZG) ","")&IF(AND($L17>9,$J17<0.75),"перерыв <45 мин (§ 4 ArbZG) ","")&IF(AND($L17>6,$L17<=9,$J17<0.5),"перерыв <30 мин (§ 4 ArbZG)",""))) | W17: =IF($H17="","",$H17) | X17: =IF($H17="","",$I17+IF($I17<=$H17,24,0)) | Y17: =IF(OR($K17="",$K17=0),0,$L17/$K17) | Z17: =IF($A17="",0,IF(WEEKDAY($A17,2)=7,1,0)) | AA17: =IF($A17="",0,IF(WEEKDAY($A17+1,2)=7,1,0)) | AB17: =IF($A17="",0,MIN(1,COUNTIF(Feiertage!$A$4:$A$43,$A17))) | AC17: =IF($A17="",0,MIN(1,COUNTIF(Feiertage!$A$4:$A$43,$A17+1))) | AD17: =IFERROR(INDEX(Feiertage!$D$4:$D$43,MATCH($A17,Feiertage!$A$4:$A$43,0)),Настройки!$D$34) | AE17: =IFERROR(INDEX(Feiertage!$D$4:$D$43,MATCH($A17+1,Feiertage!$A$4:$A$43,0)),Настройки!$D$34) | AF17: =IF($W17="",0,MAX(0,MIN($X17,Настройки!$D$25)-MAX($W17,0))+MAX(0,MIN($X17,24)-MAX($W17,Настройки!$D$24))) | AG17: =IF($W17="",0,MAX(0,MIN($X17,24+Настройки!$D$25)-MAX($W17,24))) | AH17: =IF($W17="",0,MAX(0,MIN($X17,24)-MAX($W17,0))) | AI17: =IF($W17="",0,MAX(0,MIN($X17,48)-MAX($W17,24))) | AJ17: =($Z17*$AB17*$AH17+$AA17*$AC17*$AI17)*$Y17 | AK17: =$O17-$AJ17 | AL17: =$N17-$AJ17 | AM17: =$M17-(MAX($Z17,$AB17)*$AF17+MAX($AA17,$AC17)*$AG17)*$Y17 | AN17: =IF($G17="j",Настройки!$D$27,IF($G17="n",Настройки!$D$28,IF(Настройки!$D$29="mit FZA",Настройки!$D$27,Настройки!$D$28))) | AO17: =IF($O17=0,Настройки!$D$34,($AB17*$AH17*$AD17+$AC17*$AI17*$AE17)*$Y17/$O17)
A18: =IF(14>Настройки!$D$6,"",DATE(Настройки!$D$4,Настройки!$D$5,14)) | B18: =IF($A18="","",CHOOSE(WEEKDAY($A18,2),"Пн","Вт","Ср","Чт","Пт","Сб","Вс")) | C18: =IF($A18="","",IFERROR(INDEX(Feiertage!$B$4:$B$43,MATCH($A18,Feiertage!$A$4:$A$43,0)),"")) | D18: TD | E18: Arbeit | H18: =IF($D18="ND",Настройки!$D$42,IF($D18="TD",Настройки!$D$39,"")) | I18: =IF($D18="ND",Настройки!$D$43,IF($D18="TD",Настройки!$D$40,"")) | J18: =IF($D18="ND",Настройки!$D$44,IF($D18="TD",Настройки!$D$41,"")) | K18: =IF($H18="","",$I18-$H18+IF($I18<=$H18,24,0)) | L18: =IF($K18="","",MAX(0,$K18-$J18)) | M18: =($AF18+$AG18)*$Y18 | N18: =($Z18*$AH18+$AA18*$AI18)*$Y18 | O18: =($AB18*$AH18+$AC18*$AI18)*$Y18 | P18: =IF($L18="","",MAX(0,$L18-$O18-$AL18-$AM18)) | Q18: =ROUND(Настройки!$D$10*($AK18*$AN18+$AJ18*MAX($AN18,Настройки!$D$26)+$AL18*Настройки!$D$26+$AM18*Настройки!$D$23),2) | R18: =IF($E18<>"Arbeit",0,ROUND(MIN(Настройки!$D$10,Настройки!$D$35)*($AK18*MIN($AN18,$AO18)+$AJ18*MIN(MAX($AN18,Настройки!$D$26),$AO18)+$AL18*MIN(Настройки!$D$26,Настройки!$D$33)+$AM18*MIN(Настройки!$D$23,Настройки!$D$32)),2)) | S18: =IF($E18<>"Arbeit",0,ROUND(MIN(Настройки!$D$10,Настройки!$D$36)*($AK18*MIN($AN18,$AO18)+$AJ18*MIN(MAX($AN18,Настройки!$D$26),$AO18)+$AL18*MIN(Настройки!$D$26,Настройки!$D$33)+$AM18*MIN(Настройки!$D$23,Настройки!$D$32)),2)) | T18: =IF(OR($W18="",$W17=""),"",24+$W18-$X17) | U18: =IF($L18="","",TRIM(IF($L18>10,"смена >10 ч (§ 3 / § 6 ArbZG) ","")&IF(AND($T18<>"",$T18<11),"отдых <11 ч (§ 5 ArbZG) ","")&IF(AND($L18>9,$J18<0.75),"перерыв <45 мин (§ 4 ArbZG) ","")&IF(AND($L18>6,$L18<=9,$J18<0.5),"перерыв <30 мин (§ 4 ArbZG)",""))) | W18: =IF($H18="","",$H18) | X18: =IF($H18="","",$I18+IF($I18<=$H18,24,0)) | Y18: =IF(OR($K18="",$K18=0),0,$L18/$K18) | Z18: =IF($A18="",0,IF(WEEKDAY($A18,2)=7,1,0)) | AA18: =IF($A18="",0,IF(WEEKDAY($A18+1,2)=7,1,0)) | AB18: =IF($A18="",0,MIN(1,COUNTIF(Feiertage!$A$4:$A$43,$A18))) | AC18: =IF($A18="",0,MIN(1,COUNTIF(Feiertage!$A$4:$A$43,$A18+1))) | AD18: =IFERROR(INDEX(Feiertage!$D$4:$D$43,MATCH($A18,Feiertage!$A$4:$A$43,0)),Настройки!$D$34) | AE18: =IFERROR(INDEX(Feiertage!$D$4:$D$43,MATCH($A18+1,Feiertage!$A$4:$A$43,0)),Настройки!$D$34) | AF18: =IF($W18="",0,MAX(0,MIN($X18,Настройки!$D$25)-MAX($W18,0))+MAX(0,MIN($X18,24)-MAX($W18,Настройки!$D$24))) | AG18: =IF($W18="",0,MAX(0,MIN($X18,24+Настройки!$D$25)-MAX($W18,24))) | AH18: =IF($W18="",0,MAX(0,MIN($X18,24)-MAX($W18,0))) | AI18: =IF($W18="",0,MAX(0,MIN($X18,48)-MAX($W18,24))) | AJ18: =($Z18*$AB18*$AH18+$AA18*$AC18*$AI18)*$Y18 | AK18: =$O18-$AJ18 | AL18: =$N18-$AJ18 | AM18: =$M18-(MAX($Z18,$AB18)*$AF18+MAX($AA18,$AC18)*$AG18)*$Y18 | AN18: =IF($G18="j",Настройки!$D$27,IF($G18="n",Настройки!$D$28,IF(Настройки!$D$29="mit FZA",Настройки!$D$27,Настройки!$D$28))) | AO18: =IF($O18=0,Настройки!$D$34,($AB18*$AH18*$AD18+$AC18*$AI18*$AE18)*$Y18/$O18)
A19: =IF(15>Настройки!$D$6,"",DATE(Настройки!$D$4,Настройки!$D$5,15)) | B19: =IF($A19="","",CHOOSE(WEEKDAY($A19,2),"Пн","Вт","Ср","Чт","Пт","Сб","Вс")) | C19: =IF($A19="","",IFERROR(INDEX(Feiertage!$B$4:$B$43,MATCH($A19,Feiertage!$A$4:$A$43,0)),"")) | D19: FREI | H19: =IF($D19="ND",Настройки!$D$42,IF($D19="TD",Настройки!$D$39,"")) | I19: =IF($D19="ND",Настройки!$D$43,IF($D19="TD",Настройки!$D$40,"")) | J19: =IF($D19="ND",Настройки!$D$44,IF($D19="TD",Настройки!$D$41,"")) | K19: =IF($H19="","",$I19-$H19+IF($I19<=$H19,24,0)) | L19: =IF($K19="","",MAX(0,$K19-$J19)) | M19: =($AF19+$AG19)*$Y19 | N19: =($Z19*$AH19+$AA19*$AI19)*$Y19 | O19: =($AB19*$AH19+$AC19*$AI19)*$Y19 | P19: =IF($L19="","",MAX(0,$L19-$O19-$AL19-$AM19)) | Q19: =ROUND(Настройки!$D$10*($AK19*$AN19+$AJ19*MAX($AN19,Настройки!$D$26)+$AL19*Настройки!$D$26+$AM19*Настройки!$D$23),2) | R19: =IF($E19<>"Arbeit",0,ROUND(MIN(Настройки!$D$10,Настройки!$D$35)*($AK19*MIN($AN19,$AO19)+$AJ19*MIN(MAX($AN19,Настройки!$D$26),$AO19)+$AL19*MIN(Настройки!$D$26,Настройки!$D$33)+$AM19*MIN(Настройки!$D$23,Настройки!$D$32)),2)) | S19: =IF($E19<>"Arbeit",0,ROUND(MIN(Настройки!$D$10,Настройки!$D$36)*($AK19*MIN($AN19,$AO19)+$AJ19*MIN(MAX($AN19,Настройки!$D$26),$AO19)+$AL19*MIN(Настройки!$D$26,Настройки!$D$33)+$AM19*MIN(Настройки!$D$23,Настройки!$D$32)),2)) | T19: =IF(OR($W19="",$W18=""),"",24+$W19-$X18) | U19: =IF($L19="","",TRIM(IF($L19>10,"смена >10 ч (§ 3 / § 6 ArbZG) ","")&IF(AND($T19<>"",$T19<11),"отдых <11 ч (§ 5 ArbZG) ","")&IF(AND($L19>9,$J19<0.75),"перерыв <45 мин (§ 4 ArbZG) ","")&IF(AND($L19>6,$L19<=9,$J19<0.5),"перерыв <30 мин (§ 4 ArbZG)",""))) | W19: =IF($H19="","",$H19) | X19: =IF($H19="","",$I19+IF($I19<=$H19,24,0)) | Y19: =IF(OR($K19="",$K19=0),0,$L19/$K19) | Z19: =IF($A19="",0,IF(WEEKDAY($A19,2)=7,1,0)) | AA19: =IF($A19="",0,IF(WEEKDAY($A19+1,2)=7,1,0)) | AB19: =IF($A19="",0,MIN(1,COUNTIF(Feiertage!$A$4:$A$43,$A19))) | AC19: =IF($A19="",0,MIN(1,COUNTIF(Feiertage!$A$4:$A$43,$A19+1))) | AD19: =IFERROR(INDEX(Feiertage!$D$4:$D$43,MATCH($A19,Feiertage!$A$4:$A$43,0)),Настройки!$D$34) | AE19: =IFERROR(INDEX(Feiertage!$D$4:$D$43,MATCH($A19+1,Feiertage!$A$4:$A$43,0)),Настройки!$D$34) | AF19: =IF($W19="",0,MAX(0,MIN($X19,Настройки!$D$25)-MAX($W19,0))+MAX(0,MIN($X19,24)-MAX($W19,Настройки!$D$24))) | AG19: =IF($W19="",0,MAX(0,MIN($X19,24+Настройки!$D$25)-MAX($W19,24))) | AH19: =IF($W19="",0,MAX(0,MIN($X19,24)-MAX($W19,0))) | AI19: =IF($W19="",0,MAX(0,MIN($X19,48)-MAX($W19,24))) | AJ19: =($Z19*$AB19*$AH19+$AA19*$AC19*$AI19)*$Y19 | AK19: =$O19-$AJ19 | AL19: =$N19-$AJ19 | AM19: =$M19-(MAX($Z19,$AB19)*$AF19+MAX($AA19,$AC19)*$AG19)*$Y19 | AN19: =IF($G19="j",Настройки!$D$27,IF($G19="n",Настройки!$D$28,IF(Настройки!$D$29="mit FZA",Настройки!$D$27,Настройки!$D$28))) | AO19: =IF($O19=0,Настройки!$D$34,($AB19*$AH19*$AD19+$AC19*$AI19*$AE19)*$Y19/$O19)
A20: =IF(16>Настройки!$D$6,"",DATE(Настройки!$D$4,Настройки!$D$5,16)) | B20: =IF($A20="","",CHOOSE(WEEKDAY($A20,2),"Пн","Вт","Ср","Чт","Пт","Сб","Вс")) | C20: =IF($A20="","",IFERROR(INDEX(Feiertage!$B$4:$B$43,MATCH($A20,Feiertage!$A$4:$A$43,0)),"")) | D20: FREI | H20: =IF($D20="ND",Настройки!$D$42,IF($D20="TD",Настройки!$D$39,"")) | I20: =IF($D20="ND",Настройки!$D$43,IF($D20="TD",Настройки!$D$40,"")) | J20: =IF($D20="ND",Настройки!$D$44,IF($D20="TD",Настройки!$D$41,"")) | K20: =IF($H20="","",$I20-$H20+IF($I20<=$H20,24,0)) | L20: =IF($K20="","",MAX(0,$K20-$J20)) | M20: =($AF20+$AG20)*$Y20 | N20: =($Z20*$AH20+$AA20*$AI20)*$Y20 | O20: =($AB20*$AH20+$AC20*$AI20)*$Y20 | P20: =IF($L20="","",MAX(0,$L20-$O20-$AL20-$AM20)) | Q20: =ROUND(Настройки!$D$10*($AK20*$AN20+$AJ20*MAX($AN20,Настройки!$D$26)+$AL20*Настройки!$D$26+$AM20*Настройки!$D$23),2) | R20: =IF($E20<>"Arbeit",0,ROUND(MIN(Настройки!$D$10,Настройки!$D$35)*($AK20*MIN($AN20,$AO20)+$AJ20*MIN(MAX($AN20,Настройки!$D$26),$AO20)+$AL20*MIN(Настройки!$D$26,Настройки!$D$33)+$AM20*MIN(Настройки!$D$23,Настройки!$D$32)),2)) | S20: =IF($E20<>"Arbeit",0,ROUND(MIN(Настройки!$D$10,Настройки!$D$36)*($AK20*MIN($AN20,$AO20)+$AJ20*MIN(MAX($AN20,Настройки!$D$26),$AO20)+$AL20*MIN(Настройки!$D$26,Настройки!$D$33)+$AM20*MIN(Настройки!$D$23,Настройки!$D$32)),2)) | T20: =IF(OR($W20="",$W19=""),"",24+$W20-$X19) | U20: =IF($L20="","",TRIM(IF($L20>10,"смена >10 ч (§ 3 / § 6 ArbZG) ","")&IF(AND($T20<>"",$T20<11),"отдых <11 ч (§ 5 ArbZG) ","")&IF(AND($L20>9,$J20<0.75),"перерыв <45 мин (§ 4 ArbZG) ","")&IF(AND($L20>6,$L20<=9,$J20<0.5),"перерыв <30 мин (§ 4 ArbZG)",""))) | W20: =IF($H20="","",$H20) | X20: =IF($H20="","",$I20+IF($I20<=$H20,24,0)) | Y20: =IF(OR($K20="",$K20=0),0,$L20/$K20) | Z20: =IF($A20="",0,IF(WEEKDAY($A20,2)=7,1,0)) | AA20: =IF($A20="",0,IF(WEEKDAY($A20+1,2)=7,1,0)) | AB20: =IF($A20="",0,MIN(1,COUNTIF(Feiertage!$A$4:$A$43,$A20))) | AC20: =IF($A20="",0,MIN(1,COUNTIF(Feiertage!$A$4:$A$43,$A20+1))) | AD20: =IFERROR(INDEX(Feiertage!$D$4:$D$43,MATCH($A20,Feiertage!$A$4:$A$43,0)),Настройки!$D$34) | AE20: =IFERROR(INDEX(Feiertage!$D$4:$D$43,MATCH($A20+1,Feiertage!$A$4:$A$43,0)),Настройки!$D$34) | AF20: =IF($W20="",0,MAX(0,MIN($X20,Настройки!$D$25)-MAX($W20,0))+MAX(0,MIN($X20,24)-MAX($W20,Настройки!$D$24))) | AG20: =IF($W20="",0,MAX(0,MIN($X20,24+Настройки!$D$25)-MAX($W20,24))) | AH20: =IF($W20="",0,MAX(0,MIN($X20,24)-MAX($W20,0))) | AI20: =IF($W20="",0,MAX(0,MIN($X20,48)-MAX($W20,24))) | AJ20: =($Z20*$AB20*$AH20+$AA20*$AC20*$AI20)*$Y20 | AK20: =$O20-$AJ20 | AL20: =$N20-$AJ20 | AM20: =$M20-(MAX($Z20,$AB20)*$AF20+MAX($AA20,$AC20)*$AG20)*$Y20 | AN20: =IF($G20="j",Настройки!$D$27,IF($G20="n",Настройки!$D$28,IF(Настройки!$D$29="mit FZA",Настройки!$D$27,Настройки!$D$28))) | AO20: =IF($O20=0,Настройки!$D$34,($AB20*$AH20*$AD20+$AC20*$AI20*$AE20)*$Y20/$O20)
A21: =IF(17>Настройки!$D$6,"",DATE(Настройки!$D$4,Настройки!$D$5,17)) | B21: =IF($A21="","",CHOOSE(WEEKDAY($A21,2),"Пн","Вт","Ср","Чт","Пт","Сб","Вс")) | C21: =IF($A21="","",IFERROR(INDEX(Feiertage!$B$4:$B$43,MATCH($A21,Feiertage!$A$4:$A$43,0)),"")) | D21: FREI | H21: =IF($D21="ND",Настройки!$D$42,IF($D21="TD",Настройки!$D$39,"")) | I21: =IF($D21="ND",Настройки!$D$43,IF($D21="TD",Настройки!$D$40,"")) | J21: =IF($D21="ND",Настройки!$D$44,IF($D21="TD",Настройки!$D$41,"")) | K21: =IF($H21="","",$I21-$H21+IF($I21<=$H21,24,0)) | L21: =IF($K21="","",MAX(0,$K21-$J21)) | M21: =($AF21+$AG21)*$Y21 | N21: =($Z21*$AH21+$AA21*$AI21)*$Y21 | O21: =($AB21*$AH21+$AC21*$AI21)*$Y21 | P21: =IF($L21="","",MAX(0,$L21-$O21-$AL21-$AM21)) | Q21: =ROUND(Настройки!$D$10*($AK21*$AN21+$AJ21*MAX($AN21,Настройки!$D$26)+$AL21*Настройки!$D$26+$AM21*Настройки!$D$23),2) | R21: =IF($E21<>"Arbeit",0,ROUND(MIN(Настройки!$D$10,Настройки!$D$35)*($AK21*MIN($AN21,$AO21)+$AJ21*MIN(MAX($AN21,Настройки!$D$26),$AO21)+$AL21*MIN(Настройки!$D$26,Настройки!$D$33)+$AM21*MIN(Настройки!$D$23,Настройки!$D$32)),2)) | S21: =IF($E21<>"Arbeit",0,ROUND(MIN(Настройки!$D$10,Настройки!$D$36)*($AK21*MIN($AN21,$AO21)+$AJ21*MIN(MAX($AN21,Настройки!$D$26),$AO21)+$AL21*MIN(Настройки!$D$26,Настройки!$D$33)+$AM21*MIN(Настройки!$D$23,Настройки!$D$32)),2)) | T21: =IF(OR($W21="",$W20=""),"",24+$W21-$X20) | U21: =IF($L21="","",TRIM(IF($L21>10,"смена >10 ч (§ 3 / § 6 ArbZG) ","")&IF(AND($T21<>"",$T21<11),"отдых <11 ч (§ 5 ArbZG) ","")&IF(AND($L21>9,$J21<0.75),"перерыв <45 мин (§ 4 ArbZG) ","")&IF(AND($L21>6,$L21<=9,$J21<0.5),"перерыв <30 мин (§ 4 ArbZG)",""))) | W21: =IF($H21="","",$H21) | X21: =IF($H21="","",$I21+IF($I21<=$H21,24,0)) | Y21: =IF(OR($K21="",$K21=0),0,$L21/$K21) | Z21: =IF($A21="",0,IF(WEEKDAY($A21,2)=7,1,0)) | AA21: =IF($A21="",0,IF(WEEKDAY($A21+1,2)=7,1,0)) | AB21: =IF($A21="",0,MIN(1,COUNTIF(Feiertage!$A$4:$A$43,$A21))) | AC21: =IF($A21="",0,MIN(1,COUNTIF(Feiertage!$A$4:$A$43,$A21+1))) | AD21: =IFERROR(INDEX(Feiertage!$D$4:$D$43,MATCH($A21,Feiertage!$A$4:$A$43,0)),Настройки!$D$34) | AE21: =IFERROR(INDEX(Feiertage!$D$4:$D$43,MATCH($A21+1,Feiertage!$A$4:$A$43,0)),Настройки!$D$34) | AF21: =IF($W21="",0,MAX(0,MIN($X21,Настройки!$D$25)-MAX($W21,0))+MAX(0,MIN($X21,24)-MAX($W21,Настройки!$D$24))) | AG21: =IF($W21="",0,MAX(0,MIN($X21,24+Настройки!$D$25)-MAX($W21,24))) | AH21: =IF($W21="",0,MAX(0,MIN($X21,24)-MAX($W21,0))) | AI21: =IF($W21="",0,MAX(0,MIN($X21,48)-MAX($W21,24))) | AJ21: =($Z21*$AB21*$AH21+$AA21*$AC21*$AI21)*$Y21 | AK21: =$O21-$AJ21 | AL21: =$N21-$AJ21 | AM21: =$M21-(MAX($Z21,$AB21)*$AF21+MAX($AA21,$AC21)*$AG21)*$Y21 | AN21: =IF($G21="j",Настройки!$D$27,IF($G21="n",Настройки!$D$28,IF(Настройки!$D$29="mit FZA",Настройки!$D$27,Настройки!$D$28))) | AO21: =IF($O21=0,Настройки!$D$34,($AB21*$AH21*$AD21+$AC21*$AI21*$AE21)*$Y21/$O21)
