Workbook

Sheet Dashboard
A1: Dashboard / Панель прогресса
A2: Легенда: СИНИЙ текст — то, что заполняете вы. ЧЁРНЫЙ — формулы, не редактировать. ЖЁЛТАЯ заливка — ключевое поле. Панель обновляется автоматически после заполнения листов Roadmap, Practice Log, Glossary, Video Library и Review Calendar.
A4: ОБЩИЙ ПРОГРЕСС | H4: Служебная таблица (не редактировать)
A5: Дата начала обучения | C5: ← впишите дату, когда начали курс | H5: =IFERROR(MAX('Practice Log'!$A$4:$A$200),"") | I5: =IF($H5="",0,IF(COUNTIF('Practice Log'!$A$4:$A$200,$H5)>0,1,0))
A6: Последнее обновление (последняя фактическая дата) | B6: =IFERROR(MAX(Roadmap!$N$3:$N$200),"—") | H6: =IF($H5="","",$H5-1) | I6: =IF($H6="",0,IF(COUNTIF('Practice Log'!$A$4:$A$200,$H6)>0,1,0))
A7: Всего этапов в программе | B7: =COUNT(Roadmap!$A$3:$A$200) | H7: =IF($H6="","",$H6-1) | I7: =IF($H7="",0,IF(COUNTIF('Practice Log'!$A$4:$A$200,$H7)>0,1,0))
A8: Завершено этапов | B8: =COUNTIF(Roadmap!$O$3:$O$200,"Завершено") | H8: =IF($H7="","",$H7-1) | I8: =IF($H8="",0,IF(COUNTIF('Practice Log'!$A$4:$A$200,$H8)>0,1,0))
A9: В процессе | B9: =COUNTIF(Roadmap!$O$3:$O$200,"В процессе") | H9: =IF($H8="","",$H8-1) | I9: =IF($H9="",0,IF(COUNTIF('Practice Log'!$A$4:$A$200,$H9)>0,1,0))
A10: Запланировано (не начато) | B10: =COUNTIF(Roadmap!$O$3:$O$200,"Не начато") | H10: =IF($H9="","",$H9-1) | I10: =IF($H10="",0,IF(COUNTIF('Practice Log'!$A$4:$A$200,$H10)>0,1,0))
A11: Требуют повторения | B11: =COUNTIF(Roadmap!$O$3:$O$200,"Повторить") | H11: =IF($H10="","",$H10-1) | I11: =IF($H11="",0,IF(COUNTIF('Practice Log'!$A$4:$A$200,$H11)>0,1,0))
A12: ОБЩИЙ ПРОЦЕНТ ПРОХОЖДЕНИЯ | B12: =IFERROR($B$8/$B$7,0) | H12: =IF($H11="","",$H11-1) | I12: =IF($H12="",0,IF(COUNTIF('Practice Log'!$A$4:$A$200,$H12)>0,1,0))
A13: Записей в журнале практики | B13: =COUNT('Practice Log'!$A$4:$A$200) | H13: =IF($H12="","",$H12-1) | I13: =IF($H13="",0,IF(COUNTIF('Practice Log'!$A$4:$A$200,$H13)>0,1,0))
A14: Средний балл (самооценка и тесты, 0–5) | B14: =IFERROR(AVERAGE(Roadmap!$P$3:$P$200),0) | H14: =IF($H13="","",$H13-1) | I14: =IF($H14="",0,IF(COUNTIF('Practice Log'!$A$4:$A$200,$H14)>0,1,0))
A15: Часов обучения (всего) | B15: =SUM(Roadmap!$Q$3:$Q$200) | H15: =IF($H14="","",$H14-1) | I15: =IF($H15="",0,IF(COUNTIF('Practice Log'!$A$4:$A$200,$H15)>0,1,0))
A16: Текущая серия учебных дней подряд | B16: =IFERROR(MATCH(0,$I$5:$I$64,0)-1,60) | H16: =IF($H15="","",$H15-1) | I16: =IF($H16="",0,IF(COUNTIF('Practice Log'!$A$4:$A$200,$H16)>0,1,0))
A17: Дней с последнего занятия | B17: =IF(COUNT('Practice Log'!$A$4:$A$200)=0,"—",TODAY()-MAX('Practice Log'!$A$4:$A$200)) | H17: =IF($H16="","",$H16-1) | I17: =IF($H17="",0,IF(COUNTIF('Practice Log'!$A$4:$A$200,$H17)>0,1,0))
A18: Терминов освоено (оценка 4–5) | B18: =COUNTIF(Glossary!$H$3:$H$200,">=4") | C18: из общего числа терминов в словаре | H18: =IF($H17="","",$H17-1) | I18: =IF($H18="",0,IF(COUNTIF('Practice Log'!$A$4:$A$200,$H18)>0,1,0))
A19: Всего терминов в словаре | B19: =COUNTA(Glossary!$A$3:$A$200) | H19: =IF($H18="","",$H18-1) | I19: =IF($H19="",0,IF(COUNTIF('Practice Log'!$A$4:$A$200,$H19)>0,1,0))
A20: Видео и материалов просмотрено | B20: =COUNTIF('Video Library'!$K$3:$K$100,"Просмотрено") | H20: =IF($H19="","",$H19-1) | I20: =IF($H20="",0,IF(COUNTIF('Practice Log'!$A$4:$A$200,$H20)>0,1,0))
A21: Тем к повторению СЕГОДНЯ | B21: =COUNTIF('Review Calendar'!$K$3:$K$200,"Повторить сегодня") | H21: =IF($H20="","",$H20-1) | I21: =IF($H21="",0,IF(COUNTIF('Practice Log'!$A$4:$A$200,$H21)>0,1,0))
H22: =IF($H21="","",$H21-1) | I22: =IF($H22="",0,IF(COUNTIF('Practice Log'!$A$4:$A$200,$H22)>0,1,0))
A23: РЕКОМЕНДУЕМЫЙ СЛЕДУЮЩИЙ ШАГ | H23: =IF($H22="","",$H22-1) | I23: =IF($H23="",0,IF(COUNTIF('Practice Log'!$A$4:$A$200,$H23)>0,1,0))
A24: Уровень | B24: =IFERROR(INDEX(Roadmap!$B$3:$B$200,MATCH("В процессе",Roadmap!$O$3:$O$200,0)),IFERROR(INDEX(Roadmap!$B$3:$B$200,MATCH("Не начато",Roadmap!$O$3:$O$200,0)),"")) | H24: =IF($H23="","",$H23-1) | I24: =IF($H24="",0,IF(COUNTIF('Practice Log'!$A$4:$A$200,$H24)>0,1,0))
A25: Модуль | B25: =IFERROR(INDEX(Roadmap!$C$3:$C$200,MATCH("В процессе",Roadmap!$O$3:$O$200,0)),IFERROR(INDEX(Roadmap!$C$3:$C$200,MATCH("Не начато",Roadmap!$O$3:$O$200,0)),"Все этапы завершены — переходите к самостоятельным разборам")) | H25: =IF($H24="","",$H24-1) | I25: =IF($H25="",0,IF(COUNTIF('Practice Log'!$A$4:$A$200,$H25)>0,1,0))
A26: Задание | B26: =IFERROR(INDEX(Roadmap!$K$3:$K$200,MATCH("В процессе",Roadmap!$O$3:$O$200,0)),IFERROR(INDEX(Roadmap!$K$3:$K$200,MATCH("Не начато",Roadmap!$O$3:$O$200,0)),"")) | H26: =IF($H25="","",$H25-1) | I26: =IF($H26="",0,IF(COUNTIF('Practice Log'!$A$4:$A$200,$H26)>0,1,0))
A27: Плановая дата | B27: =IFERROR(INDEX(Roadmap!$M$3:$M$200,MATCH("В процессе",Roadmap!$O$3:$O$200,0)),IFERROR(INDEX(Roadmap!$M$3:$M$200,MATCH("Не начато",Roadmap!$O$3:$O$200,0)),"")) | H27: =IF($H26="","",$H26-1) | I27: =IF($H27="",0,IF(COUNTIF('Practice Log'!$A$4:$A$200,$H27)>0,1,0))
H28: =IF($H27="","",$H27-1) | I28: =IF($H28="",0,IF(COUNTIF('Practice Log'!$A$4:$A$200,$H28)>0,1,0))
A29: ПРОГРЕСС ПО УРОВНЯМ | H29: =IF($H28="","",$H28-1) | I29: =IF($H29="",0,IF(COUNTIF('Practice Log'!$A$4:$A$200,$H29)>0,1,0))
A30: Уровень | B30: Название уровня | C30: Этапов | D30: Завершено | E30: Прогресс | F30: Средний балл | H30: =IF($H29="","",$H29-1) | I30: =IF($H30="",0,IF(COUNTIF('Practice Log'!$A$4:$A$200,$H30)>0,1,0))
A31: 0 | B31: Подготовка и базовая финансовая грамотность | C31: =COUNTIF(Roadmap!$B$3:$B$200,$A31) | D31: =COUNTIFS(Roadmap!$B$3:$B$200,$A31,Roadmap!$O$3:$O$200,"Завершено") | E31: =IFERROR($D31/$C31,0) | F31: =IFERROR(AVERAGEIF(Roadmap!$B$3:$B$200,$A31,Roadmap!$P$3:$P$200),0) | H31: =IF($H30="","",$H30-1) | I31: =IF($H31="",0,IF(COUNTIF('Practice Log'!$A$4:$A$200,$H31)>0,1,0))
A32: 1 | B32: Как работает фондовый рынок | C32: =COUNTIF(Roadmap!$B$3:$B$200,$A32) | D32: =COUNTIFS(Roadmap!$B$3:$B$200,$A32,Roadmap!$O$3:$O$200,"Завершено") | E32: =IFERROR($D32/$C32,0) | F32: =IFERROR(AVERAGEIF(Roadmap!$B$3:$B$200,$A32,Roadmap!$P$3:$P$200),0) | H32: =IF($H31="","",$H31-1) | I32: =IF($H32="",0,IF(COUNTIF('Practice Log'!$A$4:$A$200,$H32)>0,1,0))
A33: 2 | B33: Бухгалтерский и финансовый фундамент | C33: =COUNTIF(Roadmap!$B$3:$B$200,$A33) | D33: =COUNTIFS(Roadmap!$B$3:$B$200,$A33,Roadmap!$O$3:$O$200,"Завершено") | E33: =IFERROR($D33/$C33,0) | F33: =IFERROR(AVERAGEIF(Roadmap!$B$3:$B$200,$A33,Roadmap!$P$3:$P$200),0) | H33: =IF($H32="","",$H32-1) | I33: =IF($H33="",0,IF(COUNTIF('Practice Log'!$A$4:$A$200,$H33)>0,1,0))
A34: 3 | B34: Основные финансовые показатели | C34: =COUNTIF(Roadmap!$B$3:$B$200,$A34) | D34: =COUNTIFS(Roadmap!$B$3:$B$200,$A34,Roadmap!$O$3:$O$200,"Завершено") | E34: =IFERROR($D34/$C34,0) | F34: =IFERROR(AVERAGEIF(Roadmap!$B$3:$B$200,$A34,Roadmap!$P$3:$P$200),0) | H34: =IF($H33="","",$H33-1) | I34: =IF($H34="",0,IF(COUNTIF('Practice Log'!$A$4:$A$200,$H34)>0,1,0))
A35: 4 | B35: Анализ качества бизнеса | C35: =COUNTIF(Roadmap!$B$3:$B$200,$A35) | D35: =COUNTIFS(Roadmap!$B$3:$B$200,$A35,Roadmap!$O$3:$O$200,"Завершено") | E35: =IFERROR($D35/$C35,0) | F35: =IFERROR(AVERAGEIF(Roadmap!$B$3:$B$200,$A35,Roadmap!$P$3:$P$200),0) | H35: =IF($H34="","",$H34-1) | I35: =IF($H35="",0,IF(COUNTIF('Practice Log'!$A$4:$A$200,$H35)>0,1,0))
A36: 5 | B36: Анализ отрасли и конкурентов | C36: =COUNTIF(Roadmap!$B$3:$B$200,$A36) | D36: =COUNTIFS(Roadmap!$B$3:$B$200,$A36,Roadmap!$O$3:$O$200,"Завершено") | E36: =IFERROR($D36/$C36,0) | F36: =IFERROR(AVERAGEIF(Roadmap!$B$3:$B$200,$A36,Roadmap!$P$3:$P$200),0) | H36: =IF($H35="","",$H35-1) | I36: =IF($H36="",0,IF(COUNTIF('Practice Log'!$A$4:$A$200,$H36)>0,1,0))
A37: 6 | B37: Мультипликаторы и относительная оценка | C37: =COUNTIF(Roadmap!$B$3:$B$200,$A37) | D37: =COUNTIFS(Roadmap!$B$3:$B$200,$A37,Roadmap!$O$3:$O$200,"Завершено") | E37: =IFERROR($D37/$C37,0) | F37: =IFERROR(AVERAGEIF(Roadmap!$B$3:$B$200,$A37,Roadmap!$P$3:$P$200),0) | H37: =IF($H36="","",$H36-1) | I37: =IF($H37="",0,IF(COUNTIF('Practice Log'!$A$4:$A$200,$H37)>0,1,0))
A38: 7 | B38: Оценка внутренней стоимости | C38: =COUNTIF(Roadmap!$B$3:$B$200,$A38) | D38: =COUNTIFS(Roadmap!$B$3:$B$200,$A38,Roadmap!$O$3:$O$200,"Завершено") | E38: =IFERROR($D38/$C38,0) | F38: =IFERROR(AVERAGEIF(Roadmap!$B$3:$B$200,$A38,Roadmap!$P$3:$P$200),0) | H38: =IF($H37="","",$H37-1) | I38: =IF($H38="",0,IF(COUNTIF('Practice Log'!$A$4:$A$200,$H38)>0,1,0))
A39: 8 | B39: Чтение отчётности и первичных документов | C39: =COUNTIF(Roadmap!$B$3:$B$200,$A39) | D39: =COUNTIFS(Roadmap!$B$3:$B$200,$A39,Roadmap!$O$3:$O$200,"Завершено") | E39: =IFERROR($D39/$C39,0) | F39: =IFERROR(AVERAGEIF(Roadmap!$B$3:$B$200,$A39,Roadmap!$P$3:$P$200),0) | H39: =IF($H38="","",$H38-1) | I39: =IF($H39="",0,IF(COUNTIF('Practice Log'!$A$4:$A$200,$H39)>0,1,0))
A40: 9 | B40: Риски и медвежий сценарий | C40: =COUNTIF(Roadmap!$B$3:$B$200,$A40) | D40: =COUNTIFS(Roadmap!$B$3:$B$200,$A40,Roadmap!$O$3:$O$200,"Завершено") | E40: =IFERROR($D40/$C40,0) | F40: =IFERROR(AVERAGEIF(Roadmap!$B$3:$B$200,$A40,Roadmap!$P$3:$P$200),0) | H40: =IF($H39="","",$H39-1) | I40: =IF($H40="",0,IF(COUNTIF('Practice Log'!$A$4:$A$200,$H40)>0,1,0))
A41: 10 | B41: Портфель, риск и поведение инвестора | C41: =COUNTIF(Roadmap!$B$3:$B$200,$A41) | D41: =COUNTIFS(Roadmap!$B$3:$B$200,$A41,Roadmap!$O$3:$O$200,"Завершено") | E41: =IFERROR($D41/$C41,0) | F41: =IFERROR(AVERAGEIF(Roadmap!$B$3:$B$200,$A41,Roadmap!$P$3:$P$200),0) | H41: =IF($H40="","",$H40-1) | I41: =IF($H41="",0,IF(COUNTIF('Practice Log'!$A$4:$A$200,$H41)>0,1,0))
...

Sheet Roadmap
A1: Roadmap / Учебная карта: уровни 0–12 | C1: Заполняйте синие колонки: M–R (даты, статус, балл, часы, заметки). Колонка S считается автоматически. Остальное — программа курса.
A2: ID | B2: Уровень | C2: Модуль | D2: Цель: что я должен понять | E2: Предварительные знания | F2: Урок или видео | G2: YouTube-ссылка | H2: Автор / канал | I2: Язык | J2: Длительность | K2: Задание | L2: Контрольный вопрос | M2: Плановая дата | N2: Фактическая дата | O2: Статус | P2: Балл (0-5) | Q2: Время, часы | R2: Заметки: выводы и вопросы | S2: Следующий повтор
A3: 1 | B3: 0 | C3: Что такое акция | D3: Акция — доля бизнеса, а не билет лотереи | E3: — | F3: Khan Academy: Stocks and bonds | G3: https://www.youtube.com/playlist?list=PLSQl0a2vh4HD1g_teRDEUkwMIIFlB8MJv | H3: Khan Academy | I3: Английский | J3: уточнить на странице | K3: Выбрать компанию, найти тикер и биржу | L3: Чем компания отличается от её акции? | O3: Не начато | S3: =IF(N3="","",N3+7)
A4: 2 | B4: 0 | C4: Компания против акции | D4: Бизнес меняется годами, цена — ежесекундно | E4: Модуль 0.1 | F4: Раздел 0.2 учебника | H4: Учебник курса | I4: Русский | J4: — | K4: Описать бизнес компании 5 предложениями | L4: Почему хорошая компания ≠ хорошая инвестиция? | O4: Не начато | S4: =IF(N4="","",N4+7)
A5: 3 | B5: 0 | C5: Акция, облигация, ETF, индекс | D5: Разница между долей и долгом | E5: Модуль 0.1 | F5: Khan Academy: Introduction to bonds | G5: https://www.youtube.com/watch?v=Qh-M3_L4xYk | H5: Khan Academy | I5: Английский | J5: уточнить на странице | K5: Сравнить риск акции и облигации письменно | L5: Кто стоит раньше в очереди при банкротстве? | O5: Не начато | S5: =IF(N5="","",N5+7)
A6: 4 | B6: 0 | C6: Выпуск акций, IPO, вторичный рынок | D6: Куда идут деньги при покупке акции | E6: Модуль 0.3 | F6: Раздел 0.4 учебника | H6: Учебник курса | I6: Русский | J6: — | K6: Найти дату IPO своей компании | L6: Получает ли компания деньги от сделок на бирже? | O6: Не начато | S6: =IF(N6="","",N6+7)
A7: 5 | B7: 0 | C7: Акции в обращении, free float, разводнение, buyback | D7: Число акций меняет всё | E7: Модуль 0.4 | F7: Раздел 0.5 учебника | H7: Учебник курса | I7: Русский | J7: — | K7: Найти diluted shares на обложке 10-Q | L7: Что делает buyback с EPS? | O7: Не начато | S7: =IF(N7="","",N7+7)
A8: 6 | B8: 0 | C8: Рыночная капитализация | D8: Цена акции ≠ стоимость компании | E8: Модуль 0.5 | F8: Khan Academy: What it means to buy a stock | G8: https://www.youtube.com/watch?v=98qfFzqDKR8 | H8: Khan Academy | I8: Английский | J8: уточнить на странице | K8: Посчитать капитализацию вручную построчно | L8: Почему акция за 10 $ не дешевле акции за 500 $? | O8: Не начато | S8: =IF(N8="","",N8+7)
A9: 7 | B9: 0 | C9: Доходность, риск, волатильность, ликвидность | D9: Риск ≠ волатильность | E9: Модуль 0.6 | F9: Раздел 0.7 учебника | H9: Учебник курса | I9: Русский | J9: — | K9: Посчитать доходность с учётом дивиденда | L9: Чем риск отличается от волатильности? | O9: Не начато | S9: =IF(N9="","",N9+7)
A10: 8 | B10: 0 | C10: Инвестирование, трейдинг, спекуляция. Эмоции | D10: Разные горизонты и основания решений | E10: Модуль 0.7 | F10: Финансовая культура (Банк России) | G10: https://www.youtube.com/channel/UCmLiKX9HVtX2wOR1Xz9gn3A | H10: Банк России | I10: Русский | J10: уточнить на странице | K10: Составить список признаков финансовой пирамиды | L10: Что защищает от FOMO лучше силы воли? | O10: Не начато | S10: =IF(N10="","",N10+7)
A11: 9 | B11: 1 | C11: Участники рынка | D11: Кто формирует объём и цену | E11: Уровень 0 | F11: Раздел 1.1 учебника | H11: Учебник курса | I11: Русский | J11: — | K11: Найти долю институциональных держателей | L11: Обязан ли аналитик быть прав? | O11: Не начато | S11: =IF(N11="","",N11+7)
A12: 10 | B12: 1 | C12: Стакан, bid, ask, спред | D12: Спред — скрытая стоимость сделки | E12: Модуль 1.1 | F12: Раздел 1.2 учебника | H12: Учебник курса | I12: Русский | J12: — | K12: Сравнить спреды ликвидной и неликвидной бумаги | L12: Когда рыночная заявка опасна? | O12: Не начато | S12: =IF(N12="","",N12+7)
A13: 11 | B13: 1 | C13: Типы заявок и сессии | D13: Контроль цены исполнения | E13: Модуль 1.2 | F13: Обучение Московской биржи | G13: https://www.moex.com/msn/learning | H13: Московская биржа | I13: Русский | J13: уточнить на странице | K13: Описать разницу market и limit order | L13: Почему движения на премаркете обманчивы? | O13: Не начато | S13: =IF(N13="","",N13+7)
A14: 12 | B14: 1 | C14: Дивиденды и даты | D14: Дивиденд не создаёт стоимость из воздуха | E14: Модуль 1.2 | F14: Раздел 1.4 учебника | H14: Учебник курса | I14: Русский | J14: — | K14: Найти ex-dividend date и поведение цены | L14: Что происходит с ценой в дату отсечения? | O14: Не начато | S14: =IF(N14="","",N14+7)
A15: 13 | B15: 1 | C15: Дробление акций | D15: Нарезка меняется, стоимость — нет | E15: Модуль 0.6 | F15: Раздел 1.5 учебника | H15: Учебник курса | I15: Русский | J15: — | K15: Найти историю сплитов компании | L15: Меняет ли сплит капитализацию? | O15: Не начато | S15: =IF(N15="","",N15+7)
A16: 14 | B16: 1 | C16: Почему цена движется без изменений в бизнесе | D16: Рынок торгует ожиданиями | E16: Модуль 1.4 | F16: Раздел 1.6 учебника | H16: Учебник курса | I16: Русский | J16: — | K16: Найти день отчёта и объяснить реакцию цены | L16: Почему акция падает на хорошем отчёте? | O16: Не начато | S16: =IF(N16="","",N16+7)
A17: 15 | B17: 2 | C17: Income Statement | D17: Воронка от выручки до чистой прибыли | E17: Уровень 1 | F17: SEC: How to Read a 10-K | G17: https://www.sec.gov/files/reada10k.pdf | H17: U.S. SEC | I17: Английский | J17: уточнить на странице | K17: Выписать 4 ключевые строки из 10-K | L17: Что искажает чистую прибыль? | O17: Не начато | S17: =IF(N17="","",N17+7)
A18: 16 | B18: 2 | C18: Balance Sheet | D18: Активы = Обязательства + Капитал | E18: Модуль 2.1 | F18: Khan: Basic capital structure differences | G18: https://www.youtube.com/watch?v=YEZMReBbkP0 | H18: Khan Academy | I18: Английский | J18: уточнить на странице | K18: Проверить равенство баланса по отчёту | L18: Откуда берётся goodwill? | O18: Не начато | S18: =IF(N18="","",N18+7)
A19: 17 | B19: 2 | C19: Cash Flow Statement | D19: Куда реально ходили деньги | E19: Модуль 2.2 | F19: Раздел 2.3 учебника | H19: Учебник курса | I19: Русский | J19: — | K19: Посчитать FCF = OCF − CapEx построчно | L19: Почему амортизация прибавляется обратно? | O19: Не начато | S19: =IF(N19="","",N19+7)
A20: 18 | B20: 2 | C20: Связь трёх отчётов | D20: Отчёты образуют замкнутый контур | E20: Модуль 2.3 | F20: Раздел 2.4 учебника | H20: Учебник курса | I20: Русский | J20: — | K20: Нарисовать схему связей трёх отчётов | L20: Как CapEx связан с PP&E и амортизацией? | O20: Не начато | S20: =IF(N20="","",N20+7)
A21: 19 | B21: 2 | C21: Прибыль ≠ деньги | D21: Метод начисления и оборотный капитал | E21: Модуль 2.4 | F21: Раздел 2.5 учебника | H21: Учебник курса | I21: Русский | J21: — | K21: Сравнить Net Income и OCF за 3 года | L21: Назовите три причины расхождения | O21: Не начато | S21: =IF(N21="","",N21+7)
A22: 20 | B22: 2 | C22: МИНИ-ТЕСТ № 1 (уровни 0–2) | D22: Проверка перед переходом дальше | E22: Уровни 0–2 | F22: Учебник, мини-тест № 1 | H22: Учебник курса | I22: Русский | J22: — | K22: Пройти письменно, свериться с ответами | L22: Набрано ли 8 из 10? | O22: Не начато | S22: =IF(N22="","",N22+7)
A23: 21 | B23: 3 | C23: Выручка и темп роста, CAGR | D23: Из чего состоит рост | E23: Уровень 2 | F23: Раздел 3.1 учебника | H23: Учебник курса | I23: Русский | J23: — | K23: Посчитать CAGR выручки за 3 года | L23: Органический рост или поглощения? | O23: Не начато | S23: =IF(N23="","",N23+7)
A24: 22 | B24: 3 | C24: Gross Margin | D24: Структурная экономика продукта | E24: Модуль 3.1 | F24: Раздел 3.2 учебника | H24: Учебник курса | I24: Русский | J24: — | K24: Посчитать валовую маржу за 5 лет | L24: О чём говорит падающая валовая маржа? | O24: Не начато | S24: =IF(N24="","",N24+7)
A25: 23 | B25: 3 | C25: Operating Income и Operating Margin | D25: Эффективность основного бизнеса | E25: Модуль 3.2 | F25: Раздел 3.3 учебника | H25: Учебник курса | I25: Русский | J25: — | K25: Из выручки и маржи получить оп. прибыль | L25: Почему маржу сравнивают внутри отрасли? | O25: Не начато | S25: =IF(N25="","",N25+7)
A26: 24 | B26: 3 | C26: Амортизация: Depreciation и Amortization | D26: Неденежный, но реальный расход | E26: Модуль 3.3 | F26: Раздел 3.4 учебника | H26: Учебник курса | I26: Русский | J26: — | K26: Найти D&A в отчёте о движении денег | L26: Почему «ненастоящий расход» — ошибка? | O26: Не начато | S26: =IF(N26="","",N26+7)
A27: 25 | B27: 3 | C27: EBITDA, EBIT, Adjusted EBITDA | D27: Что показывает и что скрывает EBITDA | E27: Модуль 3.4 | F27: Раздел 3.5 учебника | H27: Учебник курса | I27: Русский | J27: — | K27: Посчитать EBITDA двумя способами | L27: Почему EBITDA не денежный поток? | O27: Не начато | S27: =IF(N27="","",N27+7)
A28: 26 | B28: 3 | C28: Trailing и Forward | D28: Факт против прогноза | E28: Модуль 3.5 | F28: Раздел 3.5 учебника | H28: Учебник курса | I28: Русский | J28: — | K28: Найти trailing и forward оценки, пометить тип | L28: Почему forward всегда «дешевле»? | O28: Не начато | S28: =IF(N28="","",N28+7)
A29: 27 | B29: 3 | C29: EPS и Diluted EPS | D29: Прибыль на мою долю | E29: Модуль 0.5 | F29: Khan Academy: Earnings and EPS | G29: https://www.youtube.com/watch?v=RouNXdkC0do | H29: Khan Academy | I29: Английский | J29: уточнить на странице | K29: Найти Diluted EPS и динамику акций | L29: Почему всегда diluted? | O29: Не начато | S29: =IF(N29="","",N29+7)
A30: 28 | B30: 3 | C30: OCF и Free Cash Flow | D30: Настоящие деньги бизнеса | E30: Модуль 2.3 | F30: Раздел 3.5 учебника | H30: Учебник курса | I30: Русский | J30: — | K30: Посчитать конверсию FCF/EBITDA | L30: О чём говорит низкая конверсия? | O30: Не начато | S30: =IF(N30="","",N30+7)
A31: 29 | B31: 3 | C31: ROE, ROA, ROIC | D31: Качество использования капитала | E31: Модуль 3.7 | F31: Khan Academy: ROA discussion | G31: https://www.youtube.com/watch?v=Oh4H3BJX1ZI | H31: Khan Academy | I31: Английский | J31: уточнить на странице | K31: Посчитать ROIC через NOPAT | L31: С чем обязательно сравнивать ROIC? | O31: Не начато | S31: =IF(N31="","",N31+7)
A32: 30 | B32: 3 | C32: Долговая нагрузка: Net Debt, Debt/EBITDA | D32: Долг превращает плохой год в катастрофу | E32: Модуль 3.8 | F32: Раздел 3.8 учебника | H32: Учебник курса | I32: Русский | J32: — | K32: Посчитать Net Debt и покрытие процентов | L32: Что означает отрицательный Net Debt? | O32: Не начато | S32: =IF(N32="","",N32+7)
A33: 31 | B33: 4 | C33: Бизнес-модель и источники выручки | D33: Как компания зарабатывает | E33: Уровень 3 | F33: Раздел 4.1 учебника | H33: Учебник курса | I33: Русский | J33: — | K33: Описать модель выручки и её предсказуемость | L33: Чем подписка лучше разовой продажи? | O33: Не начато | S33: =IF(N33="","",N33+7)
A34: 32 | B34: 4 | C34: Moat и конкурентные преимущества | D34: Что защищает прибыль | E34: Модуль 4.1 | F34: Раздел 4.2 учебника | H34: Учебник курса | I34: Русский | J34: — | K34: Подтвердить ров цифрами ROIC и маржи | L34: Как проверить ров количественно? | O34: Не начато | S34: =IF(N34="","",N34+7)
A35: 33 | B35: 4 | C35: TAM, доля рынка, unit economics | D35: Размер рынка и экономика клиента | E35: Модуль 4.2 | F35: Раздел 4.3 учебника | H35: Учебник курса | I35: Русский | J35: — | K35: Посчитать LTV/CAC по учебному примеру | L35: Что если LTV/CAC < 1, а выручка растёт? | O35: Не начато | S35: =IF(N35="","",N35+7)
A36: 34 | B36: 4 | C36: Цикличность, сезонность, концентрация клиентов | D36: Структурные риски бизнеса | E36: Модуль 4.3 | F36: Раздел 4.4 учебника | H36: Учебник курса | I36: Русский | J36: — | K36: Найти долю крупнейшего клиента в 10-K | L36: Почему сравнивают YoY, а не QoQ? | O36: Не начато | S36: =IF(N36="","",N36+7)
A37: 35 | B37: 4 | C37: Менеджмент и аллокация капитала | D37: Стимулы объясняют поведение | E37: Модуль 4.4 | F37: Раздел 4.5 учебника | H37: Учебник курса | I37: Русский | J37: — | K37: Сверить обещания 3-летней давности с фактом | L37: Где искать структуру вознаграждения? | O37: Не начато | S37: =IF(N37="","",N37+7)
A38: 36 | B38: 4 | C38: Признаки ухудшения бизнеса | D38: Ранние сигналы до плохих новостей | E38: Модуль 4.5 | F38: Раздел 4.6 учебника | H38: Учебник курса | I38: Русский | J38: — | K38: Пройти список из 10 признаков | L38: Какие 3 признака самые тревожные? | O38: Не начато | S38: =IF(N38="","",N38+7)
A39: 37 | B39: 5 | C39: Отрасль, конкуренты, цепочка стоимости | D39: Где концентрируется прибыль | E39: Уровень 4 | F39: Раздел 5.1 учебника | H39: Учебник курса | I39: Русский | J39: — | K39: Нарисовать цепочку и место компании | L39: Кто может съесть маржу компании? | O39: Не начато | S39: =IF(N39="","",N39+7)
A40: 38 | B40: 5 | C40: Тип отрасли и структурный рост | D40: Цикл против структурного сдвига | E40: Модуль 5.1 | F40: The Plain Bagel (критические разборы) | G40: https://www.youtube.com/ThePlainBagel | H40: The Plain Bagel | I40: Английский | J40: уточнить на странице | K40: Определить тип отрасли с обоснованием | L40: Как отличить бум от структурного роста? | O40: Не начато | S40: =IF(N40="","",N40+7)
...

Sheet Glossary
A1: Glossary / Словарь терминов | C1: Заполняйте синие колонки H и I. Термины можно добавлять своими строками — формулы Dashboard подхватят их автоматически.
A2: Термин (English) | B2: Перевод | C2: Простое объяснение | D2: Формула | E2: Пример | F2: Глава курса | G2: Ссылка на учебный материал | H2: Понял ли я (0-5) | I2: Дата повторения
A3: Market Capitalization | B3: Рыночная капитализация | C3: Стоимость всех акций компании по текущей цене | D3: Цена × Число акций | E3: 1 трлн $ ÷ 875 млн акций ≈ 1 143 $ за акцию [условие задачи из видео] | F3: 0.6 | G3: Учебник: «Анализ акций», раздел 0.6
A4: Shares Outstanding | B4: Акции в обращении | C4: Сколько всего долей компании существует | D4: Выпущенные − казначейские | E4: Смотреть на обложке 10-Q | F4: 0.5 | G4: Учебник: «Анализ акций», раздел 0.5
A5: Diluted Shares | B5: Разводнённое число акций | C5: С учётом опционов и конвертируемых бумаг | D5: — | E5: Всегда использовать вместо базового | F5: 0.5 | G5: Учебник: «Анализ акций», раздел 0.5
A6: Free Float | B6: Свободное обращение | C6: Доля акций, доступная торгам | D6: — | E6: Малый free float → высокая волатильность | F6: 0.5 | G6: Учебник: «Анализ акций», раздел 0.5
A7: Dilution | B7: Разводнение | C7: Рост числа акций уменьшает вашу долю | D7: — | E7: SBC и допэмиссии | F7: 0.5 | G7: Учебник: «Анализ акций», раздел 0.5
A8: Buyback | B8: Обратный выкуп акций | C8: Компания выкупает свои акции, доля растёт | D8: — | E8: Прибыль 100 / 45 акций вместо 50 → EPS +11% | F8: 0.5 | G8: Учебник: «Анализ акций», раздел 0.5
A9: Bid / Ask / Spread | B9: Спрос / предложение / спред | C9: Лучшие цены покупки и продажи и разница | D9: Spread = Ask − Bid | E9: 101,10 − 100,90 = 0,20 $ | F9: 1.2 | G9: Учебник: «Анализ акций», раздел 1.2
A10: Ex-dividend date | B10: Дата отсечения | C10: С этого дня акция без права на дивиденд | D10: — | E10: Цена открывается ниже примерно на дивиденд | F10: 1.4 | G10: Учебник: «Анализ акций», раздел 1.4
A11: Income Statement | B11: Отчёт о прибылях и убытках | C11: Сколько заработали за период | D11: — | E11: Revenue → Gross → Operating → Net | F11: 2.1 | G11: Учебник: «Анализ акций», раздел 2.1
A12: Balance Sheet | B12: Бухгалтерский баланс | C12: Чем владеем и кому должны на дату | D12: Активы = Обязательства + Капитал | E12: Проверка равенства обязательна | F12: 2.2 | G12: Учебник: «Анализ акций», раздел 2.2
A13: Cash Flow Statement | B13: Отчёт о движении денежных средств | C13: Куда реально ходили деньги | D13: — | E13: OCF + Investing + Financing | F13: 2.3 | G13: Учебник: «Анализ акций», раздел 2.3
A14: Goodwill | B14: Гудвил | C14: Переплата при покупке другой компании | D14: Цена − Справедливая стоимость активов | E14: Купили за 10, активы на 6 → goodwill 4 | F14: 2.2 | G14: Учебник: «Анализ акций», раздел 2.2
... A42: 10-K | B42: Годовой отчёт (США) | C42: Самый полный первоисточник о компании | D42: — | E42: SEC EDGAR | F42: 8.1 | G42: Учебник: «Анализ акций», раздел 8.1

Sheet Video Library
A1: Video Library / Библиотека видео | C1: Длительность нигде не проставлена намеренно: доступа к youtube.com у среды подготовки не было, придумывать её нельзя. Впишите фактическую длительность сами при просмотре. Заполняйте колонки G, K, M.
A2: Уровень | B2: Тема | C2: Название материала | D2: Автор / канал | E2: Ссылка | F2: Язык | G2: Длительность | H2: Качество источника | I2: Что объясняет | J2: Задание после просмотра | K2: Статус | L2: Дата проверки ссылки | M2: Заметки
A3: 0 | B3: Основы: акции и облигации | C3: Плейлист «Stocks and bonds | Finance and Capital Markets» | D3: Khan Academy | E3: https://www.youtube.com/playlist?list=PLSQl0a2vh4HD1g_teRDEUkwMIIFlB8MJv | F3: Английский | G3: уточнить на странице | H3: Официальный образовательный | I3: Что значит купить акцию, облигации, EPS, P/E, ROA | J3: Записать своими словами, что вы получаете, покупая акцию | K3: Не начато | L3: 31.08.2026
A4: 0 | B4: Что значит купить акцию | C4: What it means to buy a company's stock | D4: Khan Academy | E4: https://www.youtube.com/watch?v=98qfFzqDKR8 | F4: Английский | G4: уточнить на странице | H4: Официальный образовательный | I4: Доля владения, капитализация | J4: Посчитать капитализацию вручную | K4: Не начато | L4: 31.08.2026
A5: 0 | B5: Облигации | C5: Introduction to bonds | D5: Khan Academy | E5: https://www.youtube.com/watch?v=Qh-M3_L4xYk | F5: Английский | G5: уточнить на странице | H5: Официальный образовательный | I5: Купон, номинал, риск | J5: Сравнить риск акции и облигации письменно | K5: Не начато | L5: 31.08.2026
A6: 0 | B6: Структура капитала | C6: Basic capital structure differences | D6: Khan Academy | E6: https://www.youtube.com/watch?v=YEZMReBbkP0 | F6: Английский | G6: уточнить на странице | H6: Официальный образовательный | I6: Долг против капитала, очередь требований | J6: Найти Total Debt и Equity в балансе | K6: Не начато | L6: 31.08.2026
A7: 0 | B7: Финансовая грамотность | C7: Канал «Финансовая культура» (проект Банка России) | D7: Банк России | E7: https://www.youtube.com/channel/UCmLiKX9HVtX2wOR1Xz9gn3A | F7: Русский | G7: уточнить на странице | H7: Официальный регулятор | I7: Базовая финграмотность, защита от мошенничества | J7: Составить список признаков финансовой пирамиды | K7: Не начато | L7: 31.08.2026
A8: 0 | B8: Механика биржи | C8: Обучение для частных инвесторов (сайт) | D8: Московская биржа | E8: https://www.moex.com/msn/learning | F8: Русский | G8: уточнить на странице | H8: Официальная биржа | I8: Инструменты, механика торгов | J8: Разобрать устройство биржевого стакана | K8: Не начато | L8: 31.08.2026
A9: 3 | B9: Прибыль и EPS | C9: Earnings and EPS | D9: Khan Academy | E9: https://www.youtube.com/watch?v=RouNXdkC0do | F9: Английский | G9: уточнить на странице | H9: Официальный образовательный | I9: Прибыль, прибыль на акцию | J9: Найти Diluted EPS в 10-K | K9: Не начато | L9: 31.08.2026
A10: 3 | B10: Отдача на активы | C10: ROA discussion | D10: Khan Academy | E10: https://www.youtube.com/watch?v=Oh4H3BJX1ZI | F10: Английский | G10: уточнить на странице | H10: Официальный образовательный | I10: ROA и отдача на капитал | J10: Посчитать ROA, ROE, ROIC | K10: Не начато | L10: 31.08.2026
A11: 5 | B11: Критические разборы | C11: Канал The Plain Bagel (CFA-charterholder) | D11: The Plain Bagel | E11: https://www.youtube.com/ThePlainBagel | F11: Английский | G11: уточнить на странице | H11: Профессиональный | I11: Механика рынка, критический взгляд на популярные идеи | J11: Найти ролик с критикой популярной идеи, выписать аргументы | K11: Не начато | L11: 31.08.2026
A12: 6 | B12: Мультипликатор P/E | C12: P/E discussion | D12: Khan Academy | E12: https://www.youtube.com/watch?v=V-rko8jgJ9o | F12: Английский | G12: уточнить на странице | H12: Официальный образовательный | I12: P/E и его ограничения | J12: Посчитать P/E двух конкурентов | K12: Не начато | L12: 31.08.2026
A13: 6 | B13: Enterprise Value | C13: Investopedia Video: Introduction To Enterprise Value | D13: Investopedia | E13: https://www.youtube.com/watch?v=c8HdwcRlWZk | F13: Английский | G13: уточнить на странице | H13: Профессиональный справочник | I13: Enterprise Value против Market Cap | J13: Посчитать EV трёх компаний | K13: Не начато | L13: 31.08.2026
A14: 7 | B14: Теория финансов | C14: Курс 15.401 Finance Theory I (плейлист) | D14: MIT OpenCourseWare (проф. Эндрю Ло) | E14: https://www.youtube.com/playlist?list=PLUl4u3cNGP63B2lDhyKOsImI7FjCf6eDW | F14: Английский | G14: уточнить на странице | H14: Университетский курс | I14: Приведённая стоимость, оценка активов, портфель | J14: Решить задачу на приведённую стоимость | K14: Не начато | L14: 31.08.2026
... A21: 10 | B21: Доказательный подход | C21: Канал The Rational Reminder | D21: Rational Reminder / Ben Felix | E21: https://www.youtube.com/@rationalreminder | F21: Английский | G21: уточнить на странице | H21: Профессиональный, со ссылками на исследования | I21: Поведение инвестора, диверсификация, факторы | J21: Выписать три контринтуитивных вывода исследований | K21: Не начато | L21: 31.08.2026

Sheet Practice Log
A1: Practice Log / Журнал практики | C1: Строка 3 — ПРИМЕР заполнения (серым), удалять не обязательно: Dashboard считает записи начиная со строки 4. Каждый факт — со ссылкой на источник и страницу отчёта.
A2: Дата | B2: Компания / тикер | C2: Вид задания | D2: Использованные источники | E2: Что я анализировал | F2: Мой вывод | G2: Что оказалось сложным | H2: Ошибки | I2: Исправленный вариант | J2: Ссылка на результат работы | K2: Оценка качества (1-5) | L2: Что изучить дальше
A3: ПРИМЕР: 01.09.2026 | B3: ПРИМЕР (AAPL) | C3: Расчёт показателей | D3: 10-K FY2024, стр. 31; 10-Q Q3, обложка | E3: Капитализация и число разводнённых акций | F3: Капитализация посчитана вручную; расхождение с порталом 1,2% из-за разных дат | G3: Разница между базовым и разводнённым числом акций | H3: Сначала взял базовое число акций вместо разводнённого | I3: Пересчитал по diluted shares с обложки 10-Q | J3: Файл analysis_01.md | K3: 3 | L3: Раздел 2.1 — Income Statement

Sheet Company Analysis
A1: Company Analysis / Шаблон разбора компании (17 разделов) | D1: Заполняйте колонки D–G. Обязательно помечайте тип: факт / прогноз / допущение / мнение / вывод. Итог пишется без совета покупать или продавать.
A2: № | B2: Раздел | C2: Что нужно заполнить | D2: Мой ответ | E2: Источник факта (документ, стр., дата) | F2: Тип утверждения | G2: Статус
A3: — | B3: Шапка | C3: Компания, тикер, биржа, дата анализа, цена на дату анализа | G3: Не заполнено
A4: 1 | B4: 1. Бизнес | C4: Что продаёт, кому, как берёт деньги — 5 предложений своими словами | G4: Не заполнено
A5: 2 | B5: 2. Отрасль | C5: Тип отрасли: циклическая / защитная / структурно растущая; цепочка создания стоимости | G5: Не заполнено
A6: 3 | B6: 3. Конкуренты | C6: 3–5 конкурентов из раздела Competition в 10-K; в чём отличие компании | G6: Не заполнено
A7: 4 | B7: 4. Выручка | C7: Разбивка по сегментам и географиям за 3 года; органический и неорганический рост | G7: Не заполнено
A8: 5 | B8: 5. Прибыль | C8: Gross / Operating / Net прибыль за 5 лет; разовые статьи | G8: Не заполнено
A9: 6 | B9: 6. Маржи | C9: Gross / Operating / Net маржа за 5 лет; объяснение динамики | G9: Не заполнено
A10: 7 | B10: 7. Денежный поток | C10: OCF, CapEx, FCF; конверсия FCF/EBITDA; разрыв между Net Income и OCF | G10: Не заполнено
A11: 8 | B11: 8. Баланс | C11: Активы, денежные средства, запасы, дебиторка, goodwill | G11: Не заполнено
A12: 9 | B12: 9. Долг | C12: Net Debt, Debt/EBITDA, покрытие процентов, график погашений и ставки | G12: Не заполнено
A13: 10 | B13: 10. Количество акций | C13: Diluted shares за 5 лет, SBC в % от выручки, история buyback и цены выкупов | G13: Не заполнено
A14: 11 | B14: 11. Оценка | C14: Market Cap, EV; P/E, EV/EBITDA, EV/Sales, P/FCF (trailing); сравнение с историей и конкурентами | G14: Не заполнено
A15: 12 | B15: 11a. Обратный расчёт | C15: Какие допущения по росту оправдывают текущую цену (метод раздела 6.4) | G15: Не заполнено
... A24: 21 | B24: 19. Итог | C24: Что понял, где главная неопределённость, что буду отслеживать. Без совета покупать или продавать | G24: Не заполнено

Sheet Review Calendar
A1: Review Calendar / Календарь интервального повторения | D1: Заполняйте колонки A, B, C, I и L. Даты повторений (D–H), следующее повторение (J) и статус (K) считаются формулами автоматически.
A2: Тема или термин | B2: Уровень | C2: Дата изучения | D2: Повтор +1 день | E2: Повтор +3 дня | F2: Повтор +7 дней | G2: Повтор +14 дней | H2: Повтор +30 дней | I2: Выполнено повторов (0-5) | J2: Следующее повторение | K2: Статус | L2: Заметка
A3: Рыночная капитализация: цена × число акций | B3: 0 | D3: =IF($C3="","",$C3+1) | E3: =IF($C3="","",$C3+3) | F3: =IF($C3="","",$C3+7) | G3: =IF($C3="","",$C3+14) | H3: =IF($C3="","",$C3+30) | I3: 0 | J3: =IF($C3="","",IF($I3>=5,"",CHOOSE($I3+1,$D3,$E3,$F3,$G3,$H3))) | K3: =IF($C3="","",IF($I3>=5,"Цикл завершён",IF(TODAY()>=$J3,"Повторить сегодня",IF(TODAY()>=$J3-1,"Скоро повтор","Понятно, ждём"))))
A4: Компания против акции | B4: 0 | D4: =IF($C4="","",$C4+1) | E4: =IF($C4="","",$C4+3) | F4: =IF($C4="","",$C4+7) | G4: =IF($C4="","",$C4+14) | H4: =IF($C4="","",$C4+30) | I4: 0 | J4: =IF($C4="","",IF($I4>=5,"",CHOOSE($I4+1,$D4,$E4,$F4,$G4,$H4))) | K4: =IF($C4="","",IF($I4>=5,"Цикл завершён",IF(TODAY()>=$J4,"Повторить сегодня",IF(TODAY()>=$J4-1,"Скоро повтор","Понятно, ждём"))))
A5: Free float и разводнение | B5: 0 | D5: =IF($C5="","",$C5+1) | E5: =IF($C5="","",$C5+3) | F5: =IF($C5="","",$C5+7) | G5: =IF($C5="","",$C5+14) | H5: =IF($C5="","",$C5+30) | I5: 0 | J5: =IF($C5="","",IF($I5>=5,"",CHOOSE($I5+1,$D5,$E5,$F5,$G5,$H5))) | K5: =IF($C5="","",IF($I5>=5,"Цикл завершён",IF(TODAY()>=$J5,"Повторить сегодня",IF(TODAY()>=$J5-1,"Скоро повтор","Понятно, ждём"))))
A6: Bid, ask, спред; рыночная и лимитная заявка | B6: 1 | D6: =IF($C6="","",$C6+1) | E6: =IF($C6="","",$C6+3) | F6: =IF($C6="","",$C6+7) | G6: =IF($C6="","",$C6+14) | H6: =IF($C6="","",$C6+30) | I6: 0 | J6: =IF($C6="","",IF($I6>=5,"",CHOOSE($I6+1,$D6,$E6,$F6,$G6,$H6))) | K6: =IF($C6="","",IF($I6>=5,"Цикл завершён",IF(TODAY()>=$J6,"Повторить сегодня",IF(TODAY()>=$J6-1,"Скоро повтор","Понятно, ждём"))))
A7: Дата отсечения и поведение цены | B7: 1 | D7: =IF($C7="","",$C7+1) | E7: =IF($C7="","",$C7+3) | F7: =IF($C7="","",$C7+7) | G7: =IF($C7="","",$C7+14) | H7: =IF($C7="","",$C7+30) | I7: 0 | J7: =IF($C7="","",IF($I7>=5,"",CHOOSE($I7+1,$D7,$E7,$F7,$G7,$H7))) | K7: =IF($C7="","",IF($I7>=5,"Цикл завершён",IF(TODAY()>=$J7,"Повторить сегодня",IF(TODAY()>=$J7-1,"Скоро повтор","Понятно, ждём"))))
A8: Три отчёта и их связь | B8: 2 | D8: =IF($C8="","",$C8+1) | E8: =IF($C8="","",$C8+3) | F8: =IF($C8="","",$C8+7) | G8: =IF($C8="","",$C8+14) | H8: =IF($C8="","",$C8+30) | I8: 0 | J8: =IF($C8="","",IF($I8>=5,"",CHOOSE($I8+1,$D8,$E8,$F8,$G8,$H8))) | K8: =IF($C8="","",IF($I8>=5,"Цикл завершён",IF(TODAY()>=$J8,"Повторить сегодня",IF(TODAY()>=$J8-1,"Скоро повтор","Понятно, ждём"))))
A9: Прибыль ≠ деньги: три причины | B9: 2 | D9: =IF($C9="","",$C9+1) | E9: =IF($C9="","",$C9+3) | F9: =IF($C9="","",$C9+7) | G9: =IF($C9="","",$C9+14) | H9: =IF($C9="","",$C9+30) | I9: 0 | J9: =IF($C9="","",IF($I9>=5,"",CHOOSE($I9+1,$D9,$E9,$F9,$G9,$H9))) | K9: =IF($C9="","",IF($I9>=5,"Цикл завершён",IF(TODAY()>=$J9,"Повторить сегодня",IF(TODAY()>=$J9-1,"Скоро повтор","Понятно, ждём"))))
A10: Gross / Operating / Net маржа | B10: 3 | D10: =IF($C10="","",$C10+1) | E10: =IF($C10="","",$C10+3) | F10: =IF($C10="","",$C10+7) | G10: =IF($C10="","",$C10+14) | H10: =IF($C10="","",$C10+30) | I10: 0 | J10: =IF($C10="","",IF($I10>=5,"",CHOOSE($I10+1,$D10,$E10,$F10,$G10,$H10))) | K10: =IF($C10="","",IF($I10>=5,"Цикл завершён",IF(TODAY()>=$J10,"Повторить сегодня",IF(TODAY()>=$J10-1,"Скоро повтор","Понятно, ждём"))))
A11: EBITDA = EBIT + D&A и её ограничения | B11: 3 | D11: =IF($C11="","",$C11+1) | E11: =IF($C11="","",$C11+3) | F11: =IF($C11="","",$C11+7) | G11: =IF($C11="","",$C11+14) | H11: =IF($C11="","",$C11+30) | I11: 0 | J11: =IF($C11="","",IF($I11>=5,"",CHOOSE($I11+1,$D11,$E11,$F11,$G11,$H11))) | K11: =IF($C11="","",IF($I11>=5,"Цикл завершён",IF(TODAY()>=$J11,"Повторить сегодня",IF(TODAY()>=$J11-1,"Скоро повтор","Понятно, ждём"))))
A12: Adjusted EBITDA: что исключают и почему это спорно | B12: 3 | D12: =IF($C12="","",$C12+1) | E12: =IF($C12="","",$C12+3) | F12: =IF($C12="","",$C12+7) | G12: =IF($C12="","",$C12+14) | H12: =IF($C12="","",$C12+30) | I12: 0 | J12: =IF($C12="","",IF($I12>=5,"",CHOOSE($I12+1,$D12,$E12,$F12,$G12,$H12))) | K12: =IF($C12="","",IF($I12>=5,"Цикл завершён",IF(TODAY()>=$J12,"Повторить сегодня",IF(TODAY()>=$J12-1,"Скоро повтор","Понятно, ждём"))))
A13: Trailing против Forward | B13: 3 | D13: =IF($C13="","",$C13+1) | E13: =IF($C13="","",$C13+3) | F13: =IF($C13="","",$C13+7) | G13: =IF($C13="","",$C13+14) | H13: =IF($C13="","",$C13+30) | I13: 0 | J13: =IF($C13="","",IF($I13>=5,"",CHOOSE($I13+1,$D13,$E13,$F13,$G13,$H13))) | K13: =IF($C13="","",IF($I13>=5,"Цикл завершён",IF(TODAY()>=$J13,"Повторить сегодня",IF(TODAY()>=$J13-1,"Скоро повтор","Понятно, ждём"))))
A14: FCF = OCF − CapEx | B14: 3 | D14: =IF($C14="","",$C14+1) | E14: =IF($C14="","",$C14+3) | F14: =IF($C14="","",$C14+7) | G14: =IF($C14="","",$C14+14) | H14: =IF($C14="","",$C14+30) | I14: 0 | J14: =IF($C14="","",IF($I14>=5,"",CHOOSE($I14+1,$D14,$E14,$F14,$G14,$H14))) | K14: =IF($C14="","",IF($I14>=5,"Цикл завершён",IF(TODAY()>=$J14,"Повторить сегодня",IF(TODAY()>=$J14-1,"Скоро повтор","Понятно, ждём"))))
... A33: Ограничения технических индикаторов | B33: 11 | D33: =IF($C33="","",$C33+1) | E33: =IF($C33="","",$C33+3) | F33: =IF($C33="","",$C33+7) | G33: =IF($C33="","",$C33+14) | H33: =IF($C33="","",$C33+30) | I33: 0 | J33: =IF($C33="","",IF($I33>=5,"",CHOOSE($I33+1,$D33,$E33,$F33,$G33,$H33))) | K33: =IF($C33="","",IF($I33>=5,"Цикл завершён",IF(TODAY()>=$J33,"Повторить сегодня",IF(TODAY()>=$J33-1,"Скоро повтор","Понятно, ждём"))))

Sheet Sources
A1: Sources / Источники данных | C1: Правило курса: в анализ число попадает только из первоисточника. Агрегаторы — для быстрого взгляда, отчётность — для выводов.
A2: Название источника | B2: Тип источника | C2: Ссылка | D2: Дата проверки | E2: Какие данные можно получать | F2: Уровень надёжности | G2: Комментарий
A3: SEC EDGAR (полнотекстовый поиск) | B3: Официальный регулятор США | C3: https://www.sec.gov/edgar/search/ | D3: 31.08.2026 | E3: 10-K, 10-Q, 8-K, DEF 14A — первоисточник по компаниям США | F3: Высшая | G3: Основной источник всех фактов по американским компаниям
A4: SEC: How to Read a 10-K | B4: Официальное руководство | C4: https://www.sec.gov/files/reada10k.pdf | D4: 31.08.2026 | E4: Как устроен годовой отчёт и что читать в первую очередь | F4: Высшая | G4: Прочитать до первого самостоятельного разбора
A5: Investor.gov (SEC) | B5: Образовательный портал регулятора | C5: https://www.investor.gov/ | D5: 31.08.2026 | E5: Базовое образование, предупреждения о мошенничестве | F5: Высшая | G5: Хорош для проверки «слишком хороших» предложений
A6: Раздел Investor Relations компании | B6: Первоисточник компании | C6: Сайт конкретной компании | D6: — | E6: Отчёты, пресс-релизы, презентации, транскрипты звонков | F6: Высокая | G6: Презентации — маркетинговый документ, проверять по 10-K
A7: Московская биржа — обучение | B7: Официальная биржа | C7: https://www.moex.com/msn/learning | D7: 31.08.2026 | E7: Механика торгов, инструменты, российский рынок | F7: Высокая | G7: Русскоязычный официальный источник
A8: Школа Московской биржи | B8: Официальная биржа | C8: https://school.moex.com/ | D8: 31.08.2026 | E8: Курсы для начинающих и продвинутых | F8: Высокая | G8: Часть курсов платная
A9: Финансовая культура (Банк России) | B9: Официальный регулятор РФ | C9: https://fincult.info/ | D9: 31.08.2026 | E9: Финансовая грамотность, защита прав потребителей | F9: Высшая | G9: Русскоязычный, без продажи услуг
A10: Damodaran Online (NYU Stern) | B10: Академический источник | C10: https://pages.stern.nyu.edu/~adamodar/ | D10: 31.08.2026 | E10: Отраслевые беты, премии за риск, средние мультипликаторы, методики | F10: Высшая | G10: Эталон методологии оценки; данные обновляются ежегодно
A11: MIT OpenCourseWare 15.401 | B11: Университетский курс | C11: https://ocw.mit.edu/courses/15-401-finance-theory-i-fall-2008/ | D11: 31.08.2026 | E11: Лекции, слайды и задачи по теории финансов | F11: Высшая | G11: Требует базовой математики
A12: Investopedia | B12: Справочник | C12: https://www.investopedia.com/ | D12: 31.08.2026 | E12: Определения терминов и базовые формулы | F12: Средняя-высокая | G12: Формулы сверять с учебником и отчётностью
A13: Годовые отчёты конкурентов | B13: Первоисточник | C13: Сайты компаний | D13: — | E13: Отраслевой контекст, доли рынка, сопоставление маржи | F13: Высокая | G13: Лучший способ проверить заявления компании об отрасли
